Workbook

Sheet 1
A1: TMS 4 | B1: WR | P1: Page | Q1: 1/2
A2: DAILY PRODUCTION REPORT
A3: 46023
A4: BILLET | G4: PRODUCT
A5: Rolled | D5: Cobble | G5: A1 | M5: WIP
A6: ID | B6: Pc | C6: Kg | D6: Pc | E6: Kg | F6: % | G6: Type | H6: Section | I6: Grade | J6: Coil | K6: Kg | L6: Yield | M6: Coil | N6: Kg
G7: WR | L7: =K7/C7 -> #DIV/0!
G8: WR | L8: =K8/C8 -> #DIV/0!
G9: WR | L9: =K9/C9 -> #DIV/0!
G10: WR | L10: =K10/C10 -> #DIV/0!
G11: WR | L11: =K11/C11 -> #DIV/0!
G12: WR | L12: =K12/C12 -> #DIV/0!
G13: WR | L13: =K13/C13 -> #DIV/0!
G14: WR | L14: =K14/C14 -> #DIV/0!
G15: WR | L15: =K15/C15 -> #DIV/0!
B16: =SUM(B7:B15) -> 0 | C16: =SUM(C7:C15) -> 0 | D16: =SUM(D7:D15) -> 0 | E16: =SUM(E7:E15) -> 0 | F16: =E16/C16 -> #DIV/0! | J16: =SUM(J7:J15) -> 0 | K16: =SUM(K7:K15) -> 0 | L16: =K16/C16 -> #DIV/0! | M16: =SUM(M7:M15) -> 0 | N16: =SUM(N7:N15) -> 0
A17: Total Production A1 + WIP | K17: =K16+N16 -> 0 | L17: =K17/C16 -> #DIV/0!
A18: MONTH-TO-DATE
A19: BILLET | G19: PRODUCT
A20: Rolled | D20: Cobble | G20: A1 | M20: WIP
B21: Pc | C21: Kg | D21: Pc | E21: Kg | F21: % | G21: Type | J21: Coil | K21: Kg | L21: Yield | M21: Coil | N21: Kg
B22: =B16 -> 0 | C22: =C16 -> 0 | D22: =D16 -> 0 | E22: =E16 -> 0 | F22: =E22/C22 -> #DIV/0! | G22: WR | J22: =J16 -> 0 | K22: =K16 -> 0 | L22: =K22/C22 -> #DIV/0! | M22: =M16 -> 0 | N22: =N16 -> 0
B23: 0 | C23: 0 | D23: 0 | E23: 0 | F23: =E23/C23 -> #DIV/0! | G23: BIC | J23: 0 | K23: 0 | L23: =K23/C23 -> #DIV/0! | M23: 0 | N23: 0
B24: 0 | C24: 0 | D24: 0 | E24: 0 | F24: =E24/C24 -> #DIV/0! | G24: MIC | J24: 0 | K24: 0 | L24: =K24/C24 -> #DIV/0! | M24: 0 | N24: 0
B26: =SUM(B21:B25) -> 0 | C26: =SUM(C21:C25) -> 0 | D26: =SUM(D21:D25) -> 0 | E26: =SUM(E22:E25) -> 0 | F26: =E26/C26 -> #DIV/0! | J26: =SUM(J22:J25) -> 0 | K26: =SUM(K22:K25) -> 0 | L26: =K26/C26 -> #DIV/0! | M26: =SUM(M22:M25) -> 0 | N26: =SUM(N22:N25) -> 0
A27: Total Production A1 + WIP | K27: =K26+N26 -> 0 | L27: =K27/C26 -> #DIV/0!
A29: Type | B29: Section | C29: Grade | D29: Coil | E29: Kg | G29: Type | H29: Section | I29: Grade | J29: Coil | K29: Kg | M29: Type | N29: Section | O29: Grade | P29: Coil | Q29: Kg
A30: WR | G30: WR | M30: WR
A31: WR | G31: WR | M31: WR
A32: WR | G32: WR | M32: WR
A33: WR | G33: WR | M33: WR
A34: WR | G34: WR | M34: WR
A35: WR | G35: WR | M35: WR
A36: WR | G36: WR | M36: WR
A37: WR | G37: WR | M37: WR
A38: WR | G38: WR | M38: WR
A39: WR | G39: WR | M39: WR
A40: WR | G40: WR | M40: WR
A41: WR | G41: WR | M41: WR
... A49: WR | G49: WR | M49: WR
...

Sheet 2
A1: TMS 4 | B1: WR | P1: Page | Q1: 1/2
A2: DAILY PRODUCTION REPORT
A3: ='1'!A3:Q3+1 -> 46024
A4: BILLET | G4: PRODUCT
A5: Rolled | D5: Cobble | G5: A1 | M5: WIP
A6: ID | B6: Pc | C6: Kg | D6: Pc | E6: Kg | F6: % | G6: Type | H6: Section | I6: Grade | J6: Coil | K6: Kg | L6: Yield | M6: Coil | N6: Kg
G7: WR | L7: =K7/C7 -> #DIV/0!
G8: WR | L8: =K8/C8 -> #DIV/0!
G9: WR | L9: =K9/C9 -> #DIV/0!
G10: WR | L10: =K10/C10 -> #DIV/0!
G11: WR | L11: =K11/C11 -> #DIV/0!
G12: WR | L12: =K12/C12 -> #DIV/0!
G13: WR | L13: =K13/C13 -> #DIV/0!
G14: WR | L14: =K14/C14 -> #DIV/0!
G15: WR | L15: =K15/C15 -> #DIV/0!
B16: =SUM(B7:B15) -> 0 | C16: =SUM(C7:C15) -> 0 | D16: =SUM(D7:D15) -> 0 | E16: =SUM(E7:E15) -> 0 | F16: =E16/C16 -> #DIV/0! | J16: =SUM(J7:J15) -> 0 | K16: =SUM(K7:K15) -> 0 | L16: =K16/C16 -> #DIV/0! | M16: =SUM(M7:M15) -> 0 | N16: =SUM(N7:N15) -> 0
A17: Total Production A1 + WIP | K17: =K16+N16 -> 0 | L17: =K17/C16 -> #DIV/0!
A18: MONTH-TO-DATE
A19: BILLET | G19: PRODUCT
A20: Rolled | D20: Cobble | G20: A1 | M20: WIP
B21: Pc | C21: Kg | D21: Pc | E21: Kg | F21: % | G21: Type | J21: Coil | K21: Kg | L21: Yield | M21: Coil | N21: Kg
B22: ='1'!B22+'2'!B16 -> 0 | C22: ='1'!C22+'2'!C16 -> 0 | D22: ='1'!D22+'2'!D16 -> 0 | E22: ='1'!E22+'2'!E16 -> 0 | F22: =E22/C22 -> #DIV/0! | G22: WR | J22: ='1'!J22+'2'!J16 -> 0 | K22: ='1'!K22+'2'!K16 -> 0 | L22: =K22/C22 -> #DIV/0! | M22: ='1'!M22+'2'!M16 -> 0 | N22: ='1'!N22+'2'!N16 -> 0
B23: ='1'!B23 -> 0 | C23: ='1'!C23 -> 0 | D23: ='1'!D23 -> 0 | E23: ='1'!E23 -> 0 | F23: =E23/C23 -> #DIV/0! | G23: BIC | J23: ='1'!J23 -> 0 | K23: ='1'!K23 -> 0 | L23: =K23/C23 -> #DIV/0! | M23: ='1'!M23 -> 0 | N23: ='1'!N23 -> 0
B24: ='1'!B24 -> 0 | C24: ='1'!C24 -> 0 | D24: ='1'!D24 -> 0 | E24: ='1'!E24 -> 0 | F24: =E24/C24 -> #DIV/0! | G24: MIC | J24: ='1'!J24 -> 0 | K24: ='1'!K24 -> 0 | L24: =K24/C24 -> #DIV/0! | M24: ='1'!M24 -> 0 | N24: ='1'!N24 -> 0
B26: =SUM(B21:B25) -> 0 | C26: =SUM(C21:C25) -> 0 | D26: =SUM(D21:D25) -> 0 | E26: =SUM(E22:E25) -> 0 | F26: =E26/C26 -> #DIV/0! | J26: =SUM(J22:J25) -> 0 | K26: =SUM(K22:K25) -> 0 | L26: =K26/C26 -> #DIV/0! | M26: =SUM(M22:M25) -> 0 | N26: =SUM(N22:N25) -> 0
A27: Total Production A1 + WIP | K27: =K26+N26 -> 0 | L27: =K27/C26 -> #DIV/0!
A29: Type | B29: Section | C29: Grade | D29: Coil | E29: Kg | G29: Type | H29: Section | I29: Grade | J29: Coil | K29: Kg | M29: Type | N29: Section | O29: Grade | P29: Coil | Q29: Kg
A30: ='1'!A30 -> WR | B30: ='1'!B30 -> 0 | C30: ='1'!C30 -> 0 | D30: ='1'!D30 -> 0 | E30: ='1'!E30 -> 0 | G30: ='1'!G30 -> WR | H30: ='1'!H30 -> 0 | I30: ='1'!I30 -> 0 | J30: ='1'!J30 -> 0 | K30: ='1'!K30 -> 0 | M30: ='1'!M30 -> WR | N30: ='1'!N30 -> 0 | O30: ='1'!O30 -> 0 | P30: ='1'!P30 -> 0 | Q30: ='1'!Q30 -> 0
A31: ='1'!A31 -> WR | B31: ='1'!B31 -> 0 | C31: ='1'!C31 -> 0 | D31: ='1'!D31 -> 0 | E31: ='1'!E31 -> 0 | G31: ='1'!G31 -> WR | H31: ='1'!H31 -> 0 | I31: ='1'!I31 -> 0 | J31: ='1'!J31 -> 0 | K31: ='1'!K31 -> 0 | M31: ='1'!M31 -> WR | N31: ='1'!N31 -> 0 | O31: ='1'!O31 -> 0 | P31: ='1'!P31 -> 0 | Q31: ='1'!Q31 -> 0
A32: ='1'!A32 -> WR | B32: ='1'!B32 -> 0 | C32: ='1'!C32 -> 0 | D32: ='1'!D32 -> 0 | E32: ='1'!E32 -> 0 | G32: ='1'!G32 -> WR | H32: ='1'!H32 -> 0 | I32: ='1'!I32 -> 0 | J32: ='1'!J32 -> 0 | K32: ='1'!K32 -> 0 | M32: ='1'!M32 -> WR | N32: ='1'!N32 -> 0 | O32: ='1'!O32 -> 0 | P32: ='1'!P32 -> 0 | Q32: ='1'!Q32 -> 0
A33: ='1'!A33 -> WR | B33: ='1'!B33 -> 0 | C33: ='1'!C33 -> 0 | D33: ='1'!D33 -> 0 | E33: ='1'!E33 -> 0 | G33: ='1'!G33 -> WR | H33: ='1'!H33 -> 0 | I33: ='1'!I33 -> 0 | J33: ='1'!J33 -> 0 | K33: ='1'!K33 -> 0 | M33: ='1'!M33 -> WR | N33: ='1'!N33 -> 0 | O33: ='1'!O33 -> 0 | P33: ='1'!P33 -> 0 | Q33: ='1'!Q33 -> 0
A34: ='1'!A34 -> WR | B34: ='1'!B34 -> 0 | C34: ='1'!C34 -> 0 | D34: ='1'!D34 -> 0 | E34: ='1'!E34 -> 0 | G34: ='1'!G34 -> WR | H34: ='1'!H34 -> 0 | I34: ='1'!I34 -> 0 | J34: ='1'!J34 -> 0 | K34: ='1'!K34 -> 0 | M34: ='1'!M34 -> WR | N34: ='1'!N34 -> 0 | O34: ='1'!O34 -> 0 | P34: ='1'!P34 -> 0 | Q34: ='1'!Q34 -> 0
A35: ='1'!A35 -> WR | B35: ='1'!B35 -> 0 | C35: ='1'!C35 -> 0 | D35: ='1'!D35 -> 0 | E35: ='1'!E35 -> 0 | G35: ='1'!G35 -> WR | H35: ='1'!H35 -> 0 | I35: ='1'!I35 -> 0 | J35: ='1'!J35 -> 0 | K35: ='1'!K35 -> 0 | M35: ='1'!M35 -> WR | N35: ='1'!N35 -> 0 | O35: ='1'!O35 -> 0 | P35: ='1'!P35 -> 0 | Q35: ='1'!Q35 -> 0
A36: ='1'!A36 -> WR | B36: ='1'!B36 -> 0 | C36: ='1'!C36 -> 0 | D36: ='1'!D36 -> 0 | E36: ='1'!E36 -> 0 | G36: ='1'!G36 -> WR | H36: ='1'!H36 -> 0 | I36: ='1'!I36 -> 0 | J36: ='1'!J36 -> 0 | K36: ='1'!K36 -> 0 | M36: ='1'!M36 -> WR | N36: ='1'!N36 -> 0 | O36: ='1'!O36 -> 0 | P36: ='1'!P36 -> 0 | Q36: ='1'!Q36 -> 0
A37: ='1'!A37 -> WR | B37: ='1'!B37 -> 0 | C37: ='1'!C37 -> 0 | D37: ='1'!D37 -> 0 | E37: ='1'!E37 -> 0 | G37: ='1'!G37 -> WR | H37: ='1'!H37 -> 0 | I37: ='1'!I37 -> 0 | J37: ='1'!J37 -> 0 | K37: ='1'!K37 -> 0 | M37: ='1'!M37 -> WR | N37: ='1'!N37 -> 0 | O37: ='1'!O37 -> 0 | P37: ='1'!P37 -> 0 | Q37: ='1'!Q37 -> 0
A38: ='1'!A38 -> WR | B38: ='1'!B38 -> 0 | C38: ='1'!C38 -> 0 | D38: ='1'!D38 -> 0 | E38: ='1'!E38 -> 0 | G38: ='1'!G38 -> WR | H38: ='1'!H38 -> 0 | I38: ='1'!I38 -> 0 | J38: ='1'!J38 -> 0 | K38: ='1'!K38 -> 0 | M38: ='1'!M38 -> WR | N38: ='1'!N38 -> 0 | O38: ='1'!O38 -> 0 | P38: ='1'!P38 -> 0 | Q38: ='1'!Q38 -> 0
A39: ='1'!A39 -> WR | B39: ='1'!B39 -> 0 | C39: ='1'!C39 -> 0 | D39: ='1'!D39 -> 0 | E39: ='1'!E39 -> 0 | G39: ='1'!G39 -> WR | H39: ='1'!H39 -> 0 | I39: ='1'!I39 -> 0 | J39: ='1'!J39 -> 0 | K39: ='1'!K39 -> 0 | M39: ='1'!M39 -> WR | N39: ='1'!N39 -> 0 | O39: ='1'!O39 -> 0 | P39: ='1'!P39 -> 0 | Q39: ='1'!Q39 -> 0
A40: ='1'!A40 -> WR | B40: ='1'!B40 -> 0 | C40: ='1'!C40 -> 0 | D40: ='1'!D40 -> 0 | E40: ='1'!E40 -> 0 | G40: ='1'!G40 -> WR | H40: ='1'!H40 -> 0 | I40: ='1'!I40 -> 0 | J40: ='1'!J40 -> 0 | K40: ='1'!K40 -> 0 | M40: ='1'!M40 -> WR | N40: ='1'!N40 -> 0 | O40: ='1'!O40 -> 0 | P40: ='1'!P40 -> 0 | Q40: ='1'!Q40 -> 0
A41: ='1'!A41 -> WR | B41: ='1'!B41 -> 0 | C41: ='1'!C41 -> 0 | D41: ='1'!D41 -> 0 | E41: ='1'!E41 -> 0 | G41: ='1'!G41 -> WR | H41: ='1'!H41 -> 0 | I41: ='1'!I41 -> 0 | J41: ='1'!J41 -> 0 | K41: ='1'!K41 -> 0 | M41: ='1'!M41 -> WR | N41: ='1'!N41 -> 0 | O41: ='1'!O41 -> 0 | P41: ='1'!P41 -> 0 | Q41: ='1'!Q41 -> 0
... A49: ='1'!A49 -> WR | B49: ='1'!B49 -> 0 | C49: ='1'!C49 -> 0 | D49: ='1'!D49 -> 0 | E49: ='1'!E49 -> 0 | G49: ='1'!G49 -> WR | H49: ='1'!H49 -> 0 | I49: ='1'!I49 -> 0 | J49: ='1'!J49 -> 0 | K49: ='1'!K49 -> 0 | M49: ='1'!M49 -> WR | N49: ='1'!N49 -> 0 | O49: ='1'!O49 -> 0 | P49: ='1'!P49 -> 0 | Q49: ='1'!Q49 -> 0
...

Sheet 3
A1: TMS 4 | B1: WR | P1: Page | Q1: 1/2
A2: DAILY PRODUCTION REPORT
A3: ='2'!A3:Q3+1 -> 46025
A4: BILLET | G4: PRODUCT
A5: Rolled | D5: Cobble | G5: A1 | M5: WIP
A6: ID | B6: Pc | C6: Kg | D6: Pc | E6: Kg | F6: % | G6: Type | H6: Section | I6: Grade | J6: Coil | K6: Kg | L6: Yield | M6: Coil | N6: Kg
G7: WR | L7: =K7/C7 -> #DIV/0!
G8: WR | L8: =K8/C8 -> #DIV/0!
G9: WR | L9: =K9/C9 -> #DIV/0!
G10: WR | L10: =K10/C10 -> #DIV/0!
G11: WR | L11: =K11/C11 -> #DIV/0!
G12: WR | L12: =K12/C12 -> #DIV/0!
G13: WR | L13: =K13/C13 -> #DIV/0!
G14: WR | L14: =K14/C14 -> #DIV/0!
G15: WR | L15: =K15/C15 -> #DIV/0!
B16: =SUM(B7:B15) -> 0 | C16: =SUM(C7:C15) -> 0 | D16: =SUM(D7:D15) -> 0 | E16: =SUM(E7:E15) -> 0 | F16: =E16/C16 -> #DIV/0! | J16: =SUM(J7:J15) -> 0 | K16: =SUM(K7:K15) -> 0 | L16: =K16/C16 -> #DIV/0! | M16: =SUM(M7:M15) -> 0 | N16: =SUM(N7:N15) -> 0
A17: Total Production A1 + WIP | K17: =K16+N16 -> 0 | L17: =K17/C16 -> #DIV/0!
A18: MONTH-TO-DATE
A19: BILLET | G19: PRODUCT
A20: Rolled | D20: Cobble | G20: A1 | M20: WIP
B21: Pc | C21: Kg | D21: Pc | E21: Kg | F21: % | G21: Type | J21: Coil | K21: Kg | L21: Yield | M21: Coil | N21: Kg
B22: ='2'!B22+'3'!B16 -> 0 | C22: ='2'!C22+'3'!C16 -> 0 | D22: ='2'!D22+'3'!D16 -> 0 | E22: ='2'!E22+'3'!E16 -> 0 | F22: =E22/C22 -> #DIV/0! | G22: WR | J22: ='2'!J22+'3'!J16 -> 0 | K22: ='2'!K22+'3'!K16 -> 0 | L22: =K22/C22 -> #DIV/0! | M22: ='2'!M22+'3'!M16 -> 0 | N22: ='2'!N22+'3'!N16 -> 0
B23: ='2'!B23 -> 0 | C23: ='2'!C23 -> 0 | D23: ='2'!D23 -> 0 | E23: ='2'!E23 -> 0 | F23: =E23/C23 -> #DIV/0! | G23: BIC | J23: ='2'!J23 -> 0 | K23: ='2'!K23 -> 0 | L23: =K23/C23 -> #DIV/0! | M23: ='2'!M23 -> 0 | N23: ='2'!N23 -> 0
B24: ='2'!B24 -> 0 | C24: ='2'!C24 -> 0 | D24: ='2'!D24 -> 0 | E24: ='2'!E24 -> 0 | F24: =E24/C24 -> #DIV/0! | G24: MIC | J24: ='2'!J24 -> 0 | K24: ='2'!K24 -> 0 | L24: =K24/C24 -> #DIV/0! | M24: ='2'!M24 -> 0 | N24: ='2'!N24 -> 0
B26: =SUM(B21:B25) -> 0 | C26: =SUM(C21:C25) -> 0 | D26: =SUM(D21:D25) -> 0 | E26: =SUM(E22:E25) -> 0 | F26: =E26/C26 -> #DIV/0! | J26: =SUM(J22:J25) -> 0 | K26: =SUM(K22:K25) -> 0 | L26: =K26/C26 -> #DIV/0! | M26: =SUM(M22:M25) -> 0 | N26: =SUM(N22:N25) -> 0
A27: Total Production A1 + WIP | K27: =K26+N26 -> 0 | L27: =K27/C26 -> #DIV/0!
A29: Type | B29: Section | C29: Grade | D29: Coil | E29: Kg | G29: Type | H29: Section | I29: Grade | J29: Coil | K29: Kg | M29: Type | N29: Section | O29: Grade | P29: Coil | Q29: Kg
A30: ='2'!A30 -> WR | B30: ='2'!B30 -> 0 | C30: ='2'!C30 -> 0 | D30: ='2'!D30 -> 0 | E30: ='2'!E30 -> 0 | G30: ='2'!G30 -> WR | H30: ='2'!H30 -> 0 | I30: ='2'!I30 -> 0 | J30: ='2'!J30 -> 0 | K30: ='2'!K30 -> 0 | M30: ='2'!M30 -> WR | N30: ='2'!N30 -> 0 | O30: ='2'!O30 -> 0 | P30: ='2'!P30 -> 0 | Q30: ='2'!Q30 -> 0
A31: ='2'!A31 -> WR | B31: ='2'!B31 -> 0 | C31: ='2'!C31 -> 0 | D31: ='2'!D31 -> 0 | E31: ='2'!E31 -> 0 | G31: ='2'!G31 -> WR | H31: ='2'!H31 -> 0 | I31: ='2'!I31 -> 0 | J31: ='2'!J31 -> 0 | K31: ='2'!K31 -> 0 | M31: ='2'!M31 -> WR | N31: ='2'!N31 -> 0 | O31: ='2'!O31 -> 0 | P31: ='2'!P31 -> 0 | Q31: ='2'!Q31 -> 0
A32: ='2'!A32 -> WR | B32: ='2'!B32 -> 0 | C32: ='2'!C32 -> 0 | D32: ='2'!D32 -> 0 | E32: ='2'!E32 -> 0 | G32: ='2'!G32 -> WR | H32: ='2'!H32 -> 0 | I32: ='2'!I32 -> 0 | J32: ='2'!J32 -> 0 | K32: ='2'!K32 -> 0 | M32: ='2'!M32 -> WR | N32: ='2'!N32 -> 0 | O32: ='2'!O32 -> 0 | P32: ='2'!P32 -> 0 | Q32: ='2'!Q32 -> 0
A33: ='2'!A33 -> WR | B33: ='2'!B33 -> 0 | C33: ='2'!C33 -> 0 | D33: ='2'!D33 -> 0 | E33: ='2'!E33 -> 0 | G33: ='2'!G33 -> WR | H33: ='2'!H33 -> 0 | I33: ='2'!I33 -> 0 | J33: ='2'!J33 -> 0 | K33: ='2'!K33 -> 0 | M33: ='2'!M33 -> WR | N33: ='2'!N33 -> 0 | O33: ='2'!O33 -> 0 | P33: ='2'!P33 -> 0 | Q33: ='2'!Q33 -> 0
A34: ='2'!A34 -> WR | B34: ='2'!B34 -> 0 | C34: ='2'!C34 -> 0 | D34: ='2'!D34 -> 0 | E34: ='2'!E34 -> 0 | G34: ='2'!G34 -> WR | H34: ='2'!H34 -> 0 | I34: ='2'!I34 -> 0 | J34: ='2'!J34 -> 0 | K34: ='2'!K34 -> 0 | M34: ='2'!M34 -> WR | N34: ='2'!N34 -> 0 | O34: ='2'!O34 -> 0 | P34: ='2'!P34 -> 0 | Q34: ='2'!Q34 -> 0
A35: ='2'!A35 -> WR | B35: ='2'!B35 -> 0 | C35: ='2'!C35 -> 0 | D35: ='2'!D35 -> 0 | E35: ='2'!E35 -> 0 | G35: ='2'!G35 -> WR | H35: ='2'!H35 -> 0 | I35: ='2'!I35 -> 0 | J35: ='2'!J35 -> 0 | K35: ='2'!K35 -> 0 | M35: ='2'!M35 -> WR | N35: ='2'!N35 -> 0 | O35: ='2'!O35 -> 0 | P35: ='2'!P35 -> 0 | Q35: ='2'!Q35 -> 0
A36: ='2'!A36 -> WR | B36: ='2'!B36 -> 0 | C36: ='2'!C36 -> 0 | D36: ='2'!D36 -> 0 | E36: ='2'!E36 -> 0 | G36: ='2'!G36 -> WR | H36: ='2'!H36 -> 0 | I36: ='2'!I36 -> 0 | J36: ='2'!J36 -> 0 | K36: ='2'!K36 -> 0 | M36: ='2'!M36 -> WR | N36: ='2'!N36 -> 0 | O36: ='2'!O36 -> 0 | P36: ='2'!P36 -> 0 | Q36: ='2'!Q36 -> 0
A37: ='2'!A37 -> WR | B37: ='2'!B37 -> 0 | C37: ='2'!C37 -> 0 | D37: ='2'!D37 -> 0 | E37: ='2'!E37 -> 0 | G37: ='2'!G37 -> WR | H37: ='2'!H37 -> 0 | I37: ='2'!I37 -> 0 | J37: ='2'!J37 -> 0 | K37: ='2'!K37 -> 0 | M37: ='2'!M37 -> WR | N37: ='2'!N37 -> 0 | O37: ='2'!O37 -> 0 | P37: ='2'!P37 -> 0 | Q37: ='2'!Q37 -> 0
A38: ='2'!A38 -> WR | B38: ='2'!B38 -> 0 | C38: ='2'!C38 -> 0 | D38: ='2'!D38 -> 0 | E38: ='2'!E38 -> 0 | G38: ='2'!G38 -> WR | H38: ='2'!H38 -> 0 | I38: ='2'!I38 -> 0 | J38: ='2'!J38 -> 0 | K38: ='2'!K38 -> 0 | M38: ='2'!M38 -> WR | N38: ='2'!N38 -> 0 | O38: ='2'!O38 -> 0 | P38: ='2'!P38 -> 0 | Q38: ='2'!Q38 -> 0
A39: ='2'!A39 -> WR | B39: ='2'!B39 -> 0 | C39: ='2'!C39 -> 0 | D39: ='2'!D39 -> 0 | E39: ='2'!E39 -> 0 | G39: ='2'!G39 -> WR | H39: ='2'!H39 -> 0 | I39: ='2'!I39 -> 0 | J39: ='2'!J39 -> 0 | K39: ='2'!K39 -> 0 | M39: ='2'!M39 -> WR | N39: ='2'!N39 -> 0 | O39: ='2'!O39 -> 0 | P39: ='2'!P39 -> 0 | Q39: ='2'!Q39 -> 0
A40: ='2'!A40 -> WR | B40: ='2'!B40 -> 0 | C40: ='2'!C40 -> 0 | D40: ='2'!D40 -> 0 | E40: ='2'!E40 -> 0 | G40: ='2'!G40 -> WR | H40: ='2'!H40 -> 0 | I40: ='2'!I40 -> 0 | J40: ='2'!J40 -> 0 | K40: ='2'!K40 -> 0 | M40: ='2'!M40 -> WR | N40: ='2'!N40 -> 0 | O40: ='2'!O40 -> 0 | P40: ='2'!P40 -> 0 | Q40: ='2'!Q40 -> 0
A41: ='2'!A41 -> WR | B41: ='2'!B41 -> 0 | C41: ='2'!C41 -> 0 | D41: ='2'!D41 -> 0 | E41: ='2'!E41 -> 0 | G41: ='2'!G41 -> WR | H41: ='2'!H41 -> 0 | I41: ='2'!I41 -> 0 | J41: ='2'!J41 -> 0 | K41: ='2'!K41 -> 0 | M41: ='2'!M41 -> WR | N41: ='2'!N41 -> 0 | O41: ='2'!O41 -> 0 | P41: ='2'!P41 -> 0 | Q41: ='2'!Q41 -> 0
... A49: ='2'!A49 -> WR | B49: ='2'!B49 -> 0 | C49: ='2'!C49 -> 0 | D49: ='2'!D49 -> 0 | E49: ='2'!E49 -> 0 | G49: ='2'!G49 -> WR | H49: ='2'!H49 -> 0 | I49: ='2'!I49 -> 0 | J49: ='2'!J49 -> 0 | K49: ='2'!K49 -> 0 | M49: ='2'!M49 -> WR | N49: ='2'!N49 -> 0 | O49: ='2'!O49 -> 0 | P49: ='2'!P49 -> 0 | Q49: ='2'!Q49 -> 0
...

Sheet 4
A1: TMS 4 | B1: WR | P1: Page | Q1: 1/2
A2: DAILY PRODUCTION REPORT
A3: ='3'!A3:Q3+1 -> 46026
A4: BILLET | G4: PRODUCT
A5: Rolled | D5: Cobble | G5: A1 | M5: WIP
A6: ID | B6: Pc | C6: Kg | D6: Pc | E6: Kg | F6: % | G6: Type | H6: Section | I6: Grade | J6: Coil | K6: Kg | L6: Yield | M6: Coil | N6: Kg
G7: WR | L7: =K7/C7 -> #DIV/0!
G8: WR | L8: =K8/C8 -> #DIV/0!
G9: WR | L9: =K9/C9 -> #DIV/0!
G10: WR | L10: =K10/C10 -> #DIV/0!
G11: WR | L11: =K11/C11 -> #DIV/0!
G12: WR | L12: =K12/C12 -> #DIV/0!
G13: WR | L13: =K13/C13 -> #DIV/0!
G14: WR | L14: =K14/C14 -> #DIV/0!
G15: WR | L15: =K15/C15 -> #DIV/0!
B16: =SUM(B7:B15) -> 0 | C16: =SUM(C7:C15) -> 0 | D16: =SUM(D7:D15) -> 0 | E16: =SUM(E7:E15) -> 0 | F16: =E16/C16 -> #DIV/0! | J16: =SUM(J7:J15) -> 0 | K16: =SUM(K7:K15) -> 0 | L16: =K16/C16 -> #DIV/0! | M16: =SUM(M7:M15) -> 0 | N16: =SUM(N7:N15) -> 0
A17: Total Production A1 + WIP | K17: =K16+N16 -> 0 | L17: =K17/C16 -> #DIV/0!
A18: MONTH-TO-DATE
A19: BILLET | G19: PRODUCT
A20: Rolled | D20: Cobble | G20: A1 | M20: WIP
B21: Pc | C21: Kg | D21: Pc | E21: Kg | F21: % | G21: Type | J21: Coil | K21: Kg | L21: Yield | M21: Coil | N21: Kg
B22: ='3'!B22+'4'!B16 -> 0 | C22: ='3'!C22+'4'!C16 -> 0 | D22: ='3'!D22+'4'!D16 -> 0 | E22: ='3'!E22+'4'!E16 -> 0 | F22: =E22/C22 -> #DIV/0! | G22: WR | J22: ='3'!J22+'4'!J16 -> 0 | K22: ='3'!K22+'4'!K16 -> 0 | L22: =K22/C22 -> #DIV/0! | M22: ='3'!M22+'4'!M16 -> 0 | N22: ='3'!N22+'4'!N16 -> 0
B23: ='3'!B23 -> 0 | C23: ='3'!C23 -> 0 | D23: ='3'!D23 -> 0 | E23: ='3'!E23 -> 0 | F23: =E23/C23 -> #DIV/0! | G23: BIC | J23: ='3'!J23 -> 0 | K23: ='3'!K23 -> 0 | L23: =K23/C23 -> #DIV/0! | M23: ='3'!M23 -> 0 | N23: ='3'!N23 -> 0
B24: ='3'!B24 -> 0 | C24: ='3'!C24 -> 0 | D24: ='3'!D24 -> 0 | E24: ='3'!E24 -> 0 | F24: =E24/C24 -> #DIV/0! | G24: MIC | J24: ='3'!J24 -> 0 | K24: ='3'!K24 -> 0 | L24: =K24/C24 -> #DIV/0! | M24: ='3'!M24 -> 0 | N24: ='3'!N24 -> 0
B26: =SUM(B21:B25) -> 0 | C26: =SUM(C21:C25) -> 0 | D26: =SUM(D21:D25) -> 0 | E26: =SUM(E22:E25) -> 0 | F26: =E26/C26 -> #DIV/0! | J26: =SUM(J22:J25) -> 0 | K26: =SUM(K22:K25) -> 0 | L26: =K26/C26 -> #DIV/0! | M26: =SUM(M22:M25) -> 0 | N26: =SUM(N22:N25) -> 0
A27: Total Production A1 + WIP | K27: =K26+N26 -> 0 | L27: =K27/C26 -> #DIV/0!
A29: Type | B29: Section | C29: Grade | D29: Coil | E29: Kg | G29: Type | H29: Section | I29: Grade | J29: Coil | K29: Kg | M29: Type | N29: Section | O29: Grade | P29: Coil | Q29: Kg
A30: ='3'!A30 -> WR | B30: ='3'!B30 -> 0 | C30: ='3'!C30 -> 0 | D30: ='3'!D30 -> 0 | E30: ='3'!E30 -> 0 | G30: ='3'!G30 -> WR | H30: ='3'!H30 -> 0 | I30: ='3'!I30 -> 0 | J30: ='3'!J30 -> 0 | K30: ='3'!K30 -> 0 | M30: ='3'!M30 -> WR | N30: ='3'!N30 -> 0 | O30: ='3'!O30 -> 0 | P30: ='3'!P30 -> 0 | Q30: ='3'!Q30 -> 0
A31: ='3'!A31 -> WR | B31: ='3'!B31 -> 0 | C31: ='3'!C31 -> 0 | D31: ='3'!D31 -> 0 | E31: ='3'!E31 -> 0 | G31: ='3'!G31 -> WR | H31: ='3'!H31 -> 0 | I31: ='3'!I31 -> 0 | J31: ='3'!J31 -> 0 | K31: ='3'!K31 -> 0 | M31: ='3'!M31 -> WR | N31: ='3'!N31 -> 0 | O31: ='3'!O31 -> 0 | P31: ='3'!P31 -> 0 | Q31: ='3'!Q31 -> 0
A32: ='3'!A32 -> WR | B32: ='3'!B32 -> 0 | C32: ='3'!C32 -> 0 | D32: ='3'!D32 -> 0 | E32: ='3'!E32 -> 0 | G32: ='3'!G32 -> WR | H32: ='3'!H32 -> 0 | I32: ='3'!I32 -> 0 | J32: ='3'!J32 -> 0 | K32: ='3'!K32 -> 0 | M32: ='3'!M32 -> WR | N32: ='3'!N32 -> 0 | O32: ='3'!O32 -> 0 | P32: ='3'!P32 -> 0 | Q32: ='3'!Q32 -> 0
A33: ='3'!A33 -> WR | B33: ='3'!B33 -> 0 | C33: ='3'!C33 -> 0 | D33: ='3'!D33 -> 0 | E33: ='3'!E33 -> 0 | G33: ='3'!G33 -> WR | H33: ='3'!H33 -> 0 | I33: ='3'!I33 -> 0 | J33: ='3'!J33 -> 0 | K33: ='3'!K33 -> 0 | M33: ='3'!M33 -> WR | N33: ='3'!N33 -> 0 | O33: ='3'!O33 -> 0 | P33: ='3'!P33 -> 0 | Q33: ='3'!Q33 -> 0
A34: ='3'!A34 -> WR | B34: ='3'!B34 -> 0 | C34: ='3'!C34 -> 0 | D34: ='3'!D34 -> 0 | E34: ='3'!E34 -> 0 | G34: ='3'!G34 -> WR | H34: ='3'!H34 -> 0 | I34: ='3'!I34 -> 0 | J34: ='3'!J34 -> 0 | K34: ='3'!K34 -> 0 | M34: ='3'!M34 -> WR | N34: ='3'!N34 -> 0 | O34: ='3'!O34 -> 0 | P34: ='3'!P34 -> 0 | Q34: ='3'!Q34 -> 0
A35: ='3'!A35 -> WR | B35: ='3'!B35 -> 0 | C35: ='3'!C35 -> 0 | D35: ='3'!D35 -> 0 | E35: ='3'!E35 -> 0 | G35: ='3'!G35 -> WR | H35: ='3'!H35 -> 0 | I35: ='3'!I35 -> 0 | J35: ='3'!J35 -> 0 | K35: ='3'!K35 -> 0 | M35: ='3'!M35 -> WR | N35: ='3'!N35 -> 0 | O35: ='3'!O35 -> 0 | P35: ='3'!P35 -> 0 | Q35: ='3'!Q35 -> 0
A36: ='3'!A36 -> WR | B36: ='3'!B36 -> 0 | C36: ='3'!C36 -> 0 | D36: ='3'!D36 -> 0 | E36: ='3'!E36 -> 0 | G36: ='3'!G36 -> WR | H36: ='3'!H36 -> 0 | I36: ='3'!I36 -> 0 | J36: ='3'!J36 -> 0 | K36: ='3'!K36 -> 0 | M36: ='3'!M36 -> WR | N36: ='3'!N36 -> 0 | O36: ='3'!O36 -> 0 | P36: ='3'!P36 -> 0 | Q36: ='3'!Q36 -> 0
A37: ='3'!A37 -> WR | B37: ='3'!B37 -> 0 | C37: ='3'!C37 -> 0 | D37: ='3'!D37 -> 0 | E37: ='3'!E37 -> 0 | G37: ='3'!G37 -> WR | H37: ='3'!H37 -> 0 | I37: ='3'!I37 -> 0 | J37: ='3'!J37 -> 0 | K37: ='3'!K37 -> 0 | M37: ='3'!M37 -> WR | N37: ='3'!N37 -> 0 | O37: ='3'!O37 -> 0 | P37: ='3'!P37 -> 0 | Q37: ='3'!Q37 -> 0
A38: ='3'!A38 -> WR | B38: ='3'!B38 -> 0 | C38: ='3'!C38 -> 0 | D38: ='3'!D38 -> 0 | E38: ='3'!E38 -> 0 | G38: ='3'!G38 -> WR | H38: ='3'!H38 -> 0 | I38: ='3'!I38 -> 0 | J38: ='3'!J38 -> 0 | K38: ='3'!K38 -> 0 | M38: ='3'!M38 -> WR | N38: ='3'!N38 -> 0 | O38: ='3'!O38 -> 0 | P38: ='3'!P38 -> 0 | Q38: ='3'!Q38 -> 0
A39: ='3'!A39 -> WR | B39: ='3'!B39 -> 0 | C39: ='3'!C39 -> 0 | D39: ='3'!D39 -> 0 | E39: ='3'!E39 -> 0 | G39: ='3'!G39 -> WR | H39: ='3'!H39 -> 0 | I39: ='3'!I39 -> 0 | J39: ='3'!J39 -> 0 | K39: ='3'!K39 -> 0 | M39: ='3'!M39 -> WR | N39: ='3'!N39 -> 0 | O39: ='3'!O39 -> 0 | P39: ='3'!P39 -> 0 | Q39: ='3'!Q39 -> 0
A40: ='3'!A40 -> WR | B40: ='3'!B40 -> 0 | C40: ='3'!C40 -> 0 | D40: ='3'!D40 -> 0 | E40: ='3'!E40 -> 0 | G40: ='3'!G40 -> WR | H40: ='3'!H40 -> 0 | I40: ='3'!I40 -> 0 | J40: ='3'!J40 -> 0 | K40: ='3'!K40 -> 0 | M40: ='3'!M40 -> WR | N40: ='3'!N40 -> 0 | O40: ='3'!O40 -> 0 | P40: ='3'!P40 -> 0 | Q40: ='3'!Q40 -> 0
A41: ='3'!A41 -> WR | B41: ='3'!B41 -> 0 | C41: ='3'!C41 -> 0 | D41: ='3'!D41 -> 0 | E41: ='3'!E41 -> 0 | G41: ='3'!G41 -> WR | H41: ='3'!H41 -> 0 | I41: ='3'!I41 -> 0 | J41: ='3'!J41 -> 0 | K41: ='3'!K41 -> 0 | M41: ='3'!M41 -> WR | N41: ='3'!N41 -> 0 | O41: ='3'!O41 -> 0 | P41: ='3'!P41 -> 0 | Q41: ='3'!Q41 -> 0
... A49: ='3'!A49 -> WR | B49: ='3'!B49 -> 0 | C49: ='3'!C49 -> 0 | D49: ='3'!D49 -> 0 | E49: ='3'!E49 -> 0 | G49: ='3'!G49 -> WR | H49: ='3'!H49 -> 0 | I49: ='3'!I49 -> 0 | J49: ='3'!J49 -> 0 | K49: ='3'!K49 -> 0 | M49: ='3'!M49 -> WR | N49: ='3'!N49 -> 0 | O49: ='3'!O49 -> 0 | P49: ='3'!P49 -> 0 | Q49: ='3'!Q49 -> 0
...

Sheet 5
A1: TMS 4 | B1: WR | P1: Page | Q1: 1/2
A2: DAILY PRODUCTION REPORT
A3: ='4'!A3:Q3+1 -> 46027
A4: BILLET | G4: PRODUCT
A5: Rolled | D5: Cobble | G5: A1 | M5: WIP
A6: ID | B6: Pc | C6: Kg | D6: Pc | E6: Kg | F6: % | G6: Type | H6: Section | I6: Grade | J6: Coil | K6: Kg | L6: Yield | M6: Coil | N6: Kg
G7: WR | L7: =K7/C7 -> #DIV/0!
G8: WR | L8: =K8/C8 -> #DIV/0!
G9: WR | L9: =K9/C9 -> #DIV/0!
G10: WR | L10: =K10/C10 -> #DIV/0!
G11: WR | L11: =K11/C11 -> #DIV/0!
G12: WR | L12: =K12/C12 -> #DIV/0!
G13: WR | L13: =K13/C13 -> #DIV/0!
G14: WR | L14: =K14/C14 -> #DIV/0!
G15: WR | L15: =K15/C15 -> #DIV/0!
B16: =SUM(B7:B15) -> 0 | C16: =SUM(C7:C15) -> 0 | D16: =SUM(D7:D15) -> 0 | E16: =SUM(E7:E15) -> 0 | F16: =E16/C16 -> #DIV/0! | J16: =SUM(J7:J15) -> 0 | K16: =SUM(K7:K15) -> 0 | L16: =K16/C16 -> #DIV/0! | M16: =SUM(M7:M15) -> 0 | N16: =SUM(N7:N15) -> 0
A17: Total Production A1 + WIP | K17: =K16+N16 -> 0 | L17: =K17/C16 -> #DIV/0!
A18: MONTH-TO-DATE
A19: BILLET | G19: PRODUCT
A20: Rolled | D20: Cobble | G20: A1 | M20: WIP
B21: Pc | C21: Kg | D21: Pc | E21: Kg | F21: % | G21: Type | J21: Coil | K21: Kg | L21: Yield | M21: Coil | N21: Kg
B22: ='4'!B22+'5'!B16 -> 0 | C22: ='4'!C22+'5'!C16 -> 0 | D22: ='4'!D22+'5'!D16 -> 0 | E22: ='4'!E22+'5'!E16 -> 0 | F22: =E22/C22 -> #DIV/0! | G22: WR | J22: ='4'!J22+'5'!J16 -> 0 | K22: ='4'!K22+'5'!K16 -> 0 | L22: =K22/C22 -> #DIV/0! | M22: ='4'!M22+'5'!M16 -> 0 | N22: ='4'!N22+'5'!N16 -> 0
B23: ='4'!B23 -> 0 | C23: ='4'!C23 -> 0 | D23: ='4'!D23 -> 0 | E23: ='4'!E23 -> 0 | F23: =E23/C23 -> #DIV/0! | G23: BIC | J23: ='4'!J23 -> 0 | K23: ='4'!K23 -> 0 | L23: =K23/C23 -> #DIV/0! | M23: ='4'!M23 -> 0 | N23: ='4'!N23 -> 0
B24: ='4'!B24 -> 0 | C24: ='4'!C24 -> 0 | D24: ='4'!D24 -> 0 | E24: ='4'!E24 -> 0 | F24: =E24/C24 -> #DIV/0! | G24: MIC | J24: ='4'!J24 -> 0 | K24: ='4'!K24 -> 0 | L24: =K24/C24 -> #DIV/0! | M24: ='4'!M24 -> 0 | N24: ='4'!N24 -> 0
B26: =SUM(B21:B25) -> 0 | C26: =SUM(C21:C25) -> 0 | D26: =SUM(D21:D25) -> 0 | E26: =SUM(E22:E25) -> 0 | F26: =E26/C26 -> #DIV/0! | J26: =SUM(J22:J25) -> 0 | K26: =SUM(K22:K25) -> 0 | L26: =K26/C26 -> #DIV/0! | M26: =SUM(M22:M25) -> 0 | N26: =SUM(N22:N25) -> 0
A27: Total Production A1 + WIP | K27: =K26+N26 -> 0 | L27: =K27/C26 -> #DIV/0!
A29: Type | B29: Section | C29: Grade | D29: Coil | E29: Kg | G29: Type | H29: Section | I29: Grade | J29: Coil | K29: Kg | M29: Type | N29: Section | O29: Grade | P29: Coil | Q29: Kg
A30: ='4'!A30 -> WR | B30: ='4'!B30 -> 0 | C30: ='4'!C30 -> 0 | D30: ='4'!D30 -> 0 | E30: ='4'!E30 -> 0 | G30: ='4'!G30 -> WR | H30: ='4'!H30 -> 0 | I30: ='4'!I30 -> 0 | J30: ='4'!J30 -> 0 | K30: ='4'!K30 -> 0 | M30: ='4'!M30 -> WR | N30: ='4'!N30 -> 0 | O30: ='4'!O30 -> 0 | P30: ='4'!P30 -> 0 | Q30: ='4'!Q30 -> 0
A31: ='4'!A31 -> WR | B31: ='4'!B31 -> 0 | C31: ='4'!C31 -> 0 | D31: ='4'!D31 -> 0 | E31: ='4'!E31 -> 0 | G31: ='4'!G31 -> WR | H31: ='4'!H31 -> 0 | I31: ='4'!I31 -> 0 | J31: ='4'!J31 -> 0 | K31: ='4'!K31 -> 0 | M31: ='4'!M31 -> WR | N31: ='4'!N31 -> 0 | O31: ='4'!O31 -> 0 | P31: ='4'!P31 -> 0 | Q31: ='4'!Q31 -> 0
A32: ='4'!A32 -> WR | B32: ='4'!B32 -> 0 | C32: ='4'!C32 -> 0 | D32: ='4'!D32 -> 0 | E32: ='4'!E32 -> 0 | G32: ='4'!G32 -> WR | H32: ='4'!H32 -> 0 | I32: ='4'!I32 -> 0 | J32: ='4'!J32 -> 0 | K32: ='4'!K32 -> 0 | M32: ='4'!M32 -> WR | N32: ='4'!N32 -> 0 | O32: ='4'!O32 -> 0 | P32: ='4'!P32 -> 0 | Q32: ='4'!Q32 -> 0
A33: ='4'!A33 -> WR | B33: ='4'!B33 -> 0 | C33: ='4'!C33 -> 0 | D33: ='4'!D33 -> 0 | E33: ='4'!E33 -> 0 | G33: ='4'!G33 -> WR | H33: ='4'!H33 -> 0 | I33: ='4'!I33 -> 0 | J33: ='4'!J33 -> 0 | K33: ='4'!K33 -> 0 | M33: ='4'!M33 -> WR | N33: ='4'!N33 -> 0 | O33: ='4'!O33 -> 0 | P33: ='4'!P33 -> 0 | Q33: ='4'!Q33 -> 0
A34: ='4'!A34 -> WR | B34: ='4'!B34 -> 0 | C34: ='4'!C34 -> 0 | D34: ='4'!D34 -> 0 | E34: ='4'!E34 -> 0 | G34: ='4'!G34 -> WR | H34: ='4'!H34 -> 0 | I34: ='4'!I34 -> 0 | J34: ='4'!J34 -> 0 | K34: ='4'!K34 -> 0 | M34: ='4'!M34 -> WR | N34: ='4'!N34 -> 0 | O34: ='4'!O34 -> 0 | P34: ='4'!P34 -> 0 | Q34: ='4'!Q34 -> 0
A35: ='4'!A35 -> WR | B35: ='4'!B35 -> 0 | C35: ='4'!C35 -> 0 | D35: ='4'!D35 -> 0 | E35: ='4'!E35 -> 0 | G35: ='4'!G35 -> WR | H35: ='4'!H35 -> 0 | I35: ='4'!I35 -> 0 | J35: ='4'!J35 -> 0 | K35: ='4'!K35 -> 0 | M35: ='4'!M35 -> WR | N35: ='4'!N35 -> 0 | O35: ='4'!O35 -> 0 | P35: ='4'!P35 -> 0 | Q35: ='4'!Q35 -> 0
A36: ='4'!A36 -> WR | B36: ='4'!B36 -> 0 | C36: ='4'!C36 -> 0 | D36: ='4'!D36 -> 0 | E36: ='4'!E36 -> 0 | G36: ='4'!G36 -> WR | H36: ='4'!H36 -> 0 | I36: ='4'!I36 -> 0 | J36: ='4'!J36 -> 0 | K36: ='4'!K36 -> 0 | M36: ='4'!M36 -> WR | N36: ='4'!N36 -> 0 | O36: ='4'!O36 -> 0 | P36: ='4'!P36 -> 0 | Q36: ='4'!Q36 -> 0
A37: ='4'!A37 -> WR | B37: ='4'!B37 -> 0 | C37: ='4'!C37 -> 0 | D37: ='4'!D37 -> 0 | E37: ='4'!E37 -> 0 | G37: ='4'!G37 -> WR | H37: ='4'!H37 -> 0 | I37: ='4'!I37 -> 0 | J37: ='4'!J37 -> 0 | K37: ='4'!K37 -> 0 | M37: ='4'!M37 -> WR | N37: ='4'!N37 -> 0 | O37: ='4'!O37 -> 0 | P37: ='4'!P37 -> 0 | Q37: ='4'!Q37 -> 0
A38: ='4'!A38 -> WR | B38: ='4'!B38 -> 0 | C38: ='4'!C38 -> 0 | D38: ='4'!D38 -> 0 | E38: ='4'!E38 -> 0 | G38: ='4'!G38 -> WR | H38: ='4'!H38 -> 0 | I38: ='4'!I38 -> 0 | J38: ='4'!J38 -> 0 | K38: ='4'!K38 -> 0 | M38: ='4'!M38 -> WR | N38: ='4'!N38 -> 0 | O38: ='4'!O38 -> 0 | P38: ='4'!P38 -> 0 | Q38: ='4'!Q38 -> 0
A39: ='4'!A39 -> WR | B39: ='4'!B39 -> 0 | C39: ='4'!C39 -> 0 | D39: ='4'!D39 -> 0 | E39: ='4'!E39 -> 0 | G39: ='4'!G39 -> WR | H39: ='4'!H39 -> 0 | I39: ='4'!I39 -> 0 | J39: ='4'!J39 -> 0 | K39: ='4'!K39 -> 0 | M39: ='4'!M39 -> WR | N39: ='4'!N39 -> 0 | O39: ='4'!O39 -> 0 | P39: ='4'!P39 -> 0 | Q39: ='4'!Q39 -> 0
A40: ='4'!A40 -> WR | B40: ='4'!B40 -> 0 | C40: ='4'!C40 -> 0 | D40: ='4'!D40 -> 0 | E40: ='4'!E40 -> 0 | G40: ='4'!G40 -> WR | H40: ='4'!H40 -> 0 | I40: ='4'!I40 -> 0 | J40: ='4'!J40 -> 0 | K40: ='4'!K40 -> 0 | M40: ='4'!M40 -> WR | N40: ='4'!N40 -> 0 | O40: ='4'!O40 -> 0 | P40: ='4'!P40 -> 0 | Q40: ='4'!Q40 -> 0
A41: ='4'!A41 -> WR | B41: ='4'!B41 -> 0 | C41: ='4'!C41 -> 0 | D41: ='4'!D41 -> 0 | E41: ='4'!E41 -> 0 | G41: ='4'!G41 -> WR | H41: ='4'!H41 -> 0 | I41: ='4'!I41 -> 0 | J41: ='4'!J41 -> 0 | K41: ='4'!K41 -> 0 | M41: ='4'!M41 -> WR | N41: ='4'!N41 -> 0 | O41: ='4'!O41 -> 0 | P41: ='4'!P41 -> 0 | Q41: ='4'!Q41 -> 0
... A49: ='4'!A49 -> WR | B49: ='4'!B49 -> 0 | C49: ='4'!C49 -> 0 | D49: ='4'!D49 -> 0 | E49: ='4'!E49 -> 0 | G49: ='4'!G49 -> WR | H49: ='4'!H49 -> 0 | I49: ='4'!I49 -> 0 | J49: ='4'!J49 -> 0 | K49: ='4'!K49 -> 0 | M49: ='4'!M49 -> WR | N49: ='4'!N49 -> 0 | O49: ='4'!O49 -> 0 | P49: ='4'!P49 -> 0 | Q49: ='4'!Q49 -> 0
...

Sheet 6
A1: TMS 4 | B1: WR | P1: Page | Q1: 1/2
A2: DAILY PRODUCTION REPORT
A3: ='5'!A3:Q3+1 -> 46028
A4: BILLET | G4: PRODUCT
A5: Rolled | D5: Cobble | G5: A1 | M5: WIP
A6: ID | B6: Pc | C6: Kg | D6: Pc | E6: Kg | F6: % | G6: Type | H6: Section | I6: Grade | J6: Coil | K6: Kg | L6: Yield | M6: Coil | N6: Kg
A7: 5GX-01 | B7: 248 | C7: 523032 | D7: 5 | E7: 10545 | F7: =E7/C7 -> 0.02016129 | G7: BIC | H7: P.6 | I7: BjTPG280 | J7: 239 | K7: 497038 | L7: =K7/C7 -> 0.95030132 | M7: 4 | N7: 7662
A8: 5GX-01 | B8: 8 | C8: 16872 | D8: 1 | E8: 2109 | F8: =E8/C8 -> 0.125 | G8: WR | H8: 6.5 | I8: Bj KR 15 | J8: 6 | K8: 12304 | L8: =K8/C8 -> 0.72925557 | M8: 1 | N8: 2055
A9: 5LX-03 | B9: 144 | C9: 305424 | G9: WR | H9: 6.5 | I9: Bj KR 8 | J9: 144 | K9: 301505 | L9: =K9/C9 -> 0.98716866
A10: 5GX-02 | B10: 46 | C10: 96508 | G10: WR | H10: 6.5 | I10: Bj KR 10 | J10: 46 | K10: 95025 | L10: =K10/C10 -> 0.9846334
G11: WR | L11: =K11/C11 -> #DIV/0!
G12: WR | L12: =K12/C12 -> #DIV/0!
G13: WR | L13: =K13/C13 -> #DIV/0!
G14: WR | L14: =K14/C14 -> #DIV/0!
G15: WR | L15: =K15/C15 -> #DIV/0!
B16: =SUM(B7:B15) -> 446 | C16: =SUM(C7:C15) -> 941836 | D16: =SUM(D7:D15) -> 6 | E16: =SUM(E7:E15) -> 12654 | F16: =E16/C16 -> 0.01343546 | J16: =SUM(J7:J15) -> 435 | K16: =SUM(K7:K15) -> 905872 | L16: =K16/C16 -> 0.96181501 | M16: =SUM(M7:M15) -> 5 | N16: =SUM(N7:N15) -> 9717
A17: Total Production A1 + WIP | K17: =K16+N16 -> 915589 | L17: =K17/C16 -> 0.97213209
A18: MONTH-TO-DATE
A19: BILLET | G19: PRODUCT
A20: Rolled | D20: Cobble | G20: A1 | M20: WIP
B21: Pc | C21: Kg | D21: Pc | E21: Kg | F21: % | G21: Type | J21: Coil | K21: Kg | L21: Yield | M21: Coil | N21: Kg
B22: ='5'!B22+B8+B9+B10 -> 198 | C22: ='5'!C22+C8+C9+C10 -> 418804 | D22: ='5'!D22+D8+D9+D10 -> 1 | E22: ='5'!E22+E8+E9+E10 -> 2109 | F22: =E22/C22 -> 0.0050357685 | G22: WR | J22: ='5'!J22+J8+J9+J10 -> 196 | K22: ='5'!K22+K8+K9+K10 -> 408834 | L22: =K22/C22 -> 0.97619411 | M22: ='5'!M22+M8+M9+M10 -> 1 | N22: ='5'!N22+N8+N9+N10 -> 2055
B23: =B7 -> 248 | C23: =C7 -> 523032 | D23: =D7 -> 5 | E23: =E7 -> 10545 | F23: =E23/C23 -> 0.02016129 | G23: BIC | J23: =J7 -> 239 | K23: =K7 -> 497038 | L23: =K23/C23 -> 0.95030132 | M23: =M7 -> 4 | N23: =N7 -> 7662
B24: ='5'!B24 -> 0 | C24: ='5'!C24 -> 0 | D24: ='5'!D24 -> 0 | E24: ='5'!E24 -> 0 | F24: =E24/C24 -> #DIV/0! | G24: MIC | J24: ='5'!J24 -> 0 | K24: ='5'!K24 -> 0 | L24: =K24/C24 -> #DIV/0! | M24: ='5'!M24 -> 0 | N24: ='5'!N24 -> 0
B26: =SUM(B21:B25) -> 446 | C26: =SUM(C21:C25) -> 941836 | D26: =SUM(D21:D25) -> 6 | E26: =SUM(E22:E25) -> 12654 | F26: =E26/C26 -> 0.01343546 | J26: =SUM(J22:J25) -> 435 | K26: =SUM(K22:K25) -> 905872 | L26: =K26/C26 -> 0.96181501 | M26: =SUM(M22:M25) -> 5 | N26: =SUM(N22:N25) -> 9717
A27: Total Production A1 + WIP | K27: =K26+N26 -> 915589 | L27: =K27/C26 -> 0.97213209
A29: Type | B29: Section | C29: Grade | D29: Coil | E29: Kg | G29: Type | H29: Section | I29: Grade | J29: Coil | K29: Kg | M29: Type | N29: Section | O29: Grade | P29: Coil | Q29: Kg
A30: BIC | B30: P.6 | C30: BjTPG280 | D30: =J7 -> 239 | E30: =K7 -> 497038 | G30: ='5'!G30 -> WR | H30: ='5'!H30 -> 0 | I30: ='5'!I30 -> 0 | J30: ='5'!J30 -> 0 | K30: ='5'!K30 -> 0 | M30: ='5'!M30 -> WR | N30: ='5'!N30 -> 0 | O30: ='5'!O30 -> 0 | P30: ='5'!P30 -> 0 | Q30: ='5'!Q30 -> 0
A31: ='5'!A31 -> WR | B31: 6.5 | C31: 8 | D31: =J9 -> 144 | E31: =K9 -> 301505 | G31: ='5'!G31 -> WR | H31: ='5'!H31 -> 0 | I31: ='5'!I31 -> 0 | J31: ='5'!J31 -> 0 | K31: ='5'!K31 -> 0 | M31: ='5'!M31 -> WR | N31: ='5'!N31 -> 0 | O31: ='5'!O31 -> 0 | P31: ='5'!P31 -> 0 | Q31: ='5'!Q31 -> 0
A32: ='5'!A32 -> WR | B32: 6.5 | C32: 10 | D32: =J10 -> 46 | E32: =K10 -> 95025 | G32: ='5'!G32 -> WR | H32: ='5'!H32 -> 0 | I32: ='5'!I32 -> 0 | J32: ='5'!J32 -> 0 | K32: ='5'!K32 -> 0 | M32: ='5'!M32 -> WR | N32: ='5'!N32 -> 0 | O32: ='5'!O32 -> 0 | P32: ='5'!P32 -> 0 | Q32: ='5'!Q32 -> 0
A33: ='5'!A33 -> WR | B33: 6.5 | C33: 15 | D33: =J8 -> 6 | E33: =K8 -> 12304 | G33: ='5'!G33 -> WR | H33: ='5'!H33 -> 0 | I33: ='5'!I33 -> 0 | J33: ='5'!J33 -> 0 | K33: ='5'!K33 -> 0 | M33: ='5'!M33 -> WR | N33: ='5'!N33 -> 0 | O33: ='5'!O33 -> 0 | P33: ='5'!P33 -> 0 | Q33: ='5'!Q33 -> 0
A34: ='5'!A34 -> WR | B34: ='5'!B34 -> 0 | C34: ='5'!C34 -> 0 | D34: ='5'!D34 -> 0 | E34: ='5'!E34 -> 0 | G34: ='5'!G34 -> WR | H34: ='5'!H34 -> 0 | I34: ='5'!I34 -> 0 | J34: ='5'!J34 -> 0 | K34: ='5'!K34 -> 0 | M34: ='5'!M34 -> WR | N34: ='5'!N34 -> 0 | O34: ='5'!O34 -> 0 | P34: ='5'!P34 -> 0 | Q34: ='5'!Q34 -> 0
A35: ='5'!A35 -> WR | B35: ='5'!B35 -> 0 | C35: ='5'!C35 -> 0 | D35: ='5'!D35 -> 0 | E35: ='5'!E35 -> 0 | G35: ='5'!G35 -> WR | H35: ='5'!H35 -> 0 | I35: ='5'!I35 -> 0 | J35: ='5'!J35 -> 0 | K35: ='5'!K35 -> 0 | M35: ='5'!M35 -> WR | N35: ='5'!N35 -> 0 | O35: ='5'!O35 -> 0 | P35: ='5'!P35 -> 0 | Q35: ='5'!Q35 -> 0
A36: ='5'!A36 -> WR | B36: ='5'!B36 -> 0 | C36: ='5'!C36 -> 0 | D36: ='5'!D36 -> 0 | E36: ='5'!E36 -> 0 | G36: ='5'!G36 -> WR | H36: ='5'!H36 -> 0 | I36: ='5'!I36 -> 0 | J36: ='5'!J36 -> 0 | K36: ='5'!K36 -> 0 | M36: ='5'!M36 -> WR | N36: ='5'!N36 -> 0 | O36: ='5'!O36 -> 0 | P36: ='5'!P36 -> 0 | Q36: ='5'!Q36 -> 0
A37: ='5'!A37 -> WR | B37: ='5'!B37 -> 0 | C37: ='5'!C37 -> 0 | D37: ='5'!D37 -> 0 | E37: ='5'!E37 -> 0 | G37: ='5'!G37 -> WR | H37: ='5'!H37 -> 0 | I37: ='5'!I37 -> 0 | J37: ='5'!J37 -> 0 | K37: ='5'!K37 -> 0 | M37: ='5'!M37 -> WR | N37: ='5'!N37 -> 0 | O37: ='5'!O37 -> 0 | P37: ='5'!P37 -> 0 | Q37: ='5'!Q37 -> 0
A38: ='5'!A38 -> WR | B38: ='5'!B38 -> 0 | C38: ='5'!C38 -> 0 | D38: ='5'!D38 -> 0 | E38: ='5'!E38 -> 0 | G38: ='5'!G38 -> WR | H38: ='5'!H38 -> 0 | I38: ='5'!I38 -> 0 | J38: ='5'!J38 -> 0 | K38: ='5'!K38 -> 0 | M38: ='5'!M38 -> WR | N38: ='5'!N38 -> 0 | O38: ='5'!O38 -> 0 | P38: ='5'!P38 -> 0 | Q38: ='5'!Q38 -> 0
A39: ='5'!A39 -> WR | B39: ='5'!B39 -> 0 | C39: ='5'!C39 -> 0 | D39: ='5'!D39 -> 0 | E39: ='5'!E39 -> 0 | G39: ='5'!G39 -> WR | H39: ='5'!H39 -> 0 | I39: ='5'!I39 -> 0 | J39: ='5'!J39 -> 0 | K39: ='5'!K39 -> 0 | M39: ='5'!M39 -> WR | N39: ='5'!N39 -> 0 | O39: ='5'!O39 -> 0 | P39: ='5'!P39 -> 0 | Q39: ='5'!Q39 -> 0
A40: ='5'!A40 -> WR | B40: ='5'!B40 -> 0 | C40: ='5'!C40 -> 0 | D40: ='5'!D40 -> 0 | E40: ='5'!E40 -> 0 | G40: ='5'!G40 -> WR | H40: ='5'!H40 -> 0 | I40: ='5'!I40 -> 0 | J40: ='5'!J40 -> 0 | K40: ='5'!K40 -> 0 | M40: ='5'!M40 -> WR | N40: ='5'!N40 -> 0 | O40: ='5'!O40 -> 0 | P40: ='5'!P40 -> 0 | Q40: ='5'!Q40 -> 0
A41: ='5'!A41 -> WR | B41: ='5'!B41 -> 0 | C41: ='5'!C41 -> 0 | D41: ='5'!D41 -> 0 | E41: ='5'!E41 -> 0 | G41: ='5'!G41 -> WR | H41: ='5'!H41 -> 0 | I41: ='5'!I41 -> 0 | J41: ='5'!J41 -> 0 | K41: ='5'!K41 -> 0 | M41: ='5'!M41 -> WR | N41: ='5'!N41 -> 0 | O41: ='5'!O41 -> 0 | P41: ='5'!P41 -> 0 | Q41: ='5'!Q41 -> 0
A42: ='5'!A42 -> WR | B42: ='5'!B42 -> 0 | C42: ='5'!C42 -> 0 | D42: ='5'!D42 -> 0 | E42: ='5'!E42 -> 0 | G42: ='5'!G42 -> WR | H42: ='5'!H42 -> 0 | I42: ='5'!I42 -> 0 | J42: ='5'!J42 -> 0 | K42: ='5'!K42 -> 0 | M42: ='5'!M42 -> WR | N42: ='5'!N42 -> 0 | O42: ='5'!O42 -> 0 | P42: ='5'!P42 -> 0 | Q42: ='5'!Q42 -> 0
...

Sheet 7
A1: TMS 4 | B1: WR | P1: Page | Q1: 1/2
A2: DAILY PRODUCTION REPORT
A3: ='6'!A3:Q3+1 -> 46029
A4: BILLET | G4: PRODUCT
A5: Rolled | D5: Cobble | G5: A1 | M5: WIP
A6: ID | B6: Pc | C6: Kg | D6: Pc | E6: Kg | F6: % | G6: Type | H6: Section | I6: Grade | J6: Coil | K6: Kg | L6: Yield | M6: Coil | N6: Kg
A7: 5GX-02 | B7: 2 | C7: 4196 | G7: WR | H7: 6.5 | I7: Bj KR 10 | J7: 2 | K7: 4124 | L7: =K7/C7 -> 0.9828408
A8: 5KX-06 | B8: 48 | C8: 101712 | G8: WR | H8: 5.5 | I8: Bj KR 6 | J8: 48 | K8: 100103 | L8: =K8/C8 -> 0.98418082
A9: 4LX-03 | B9: 144 | C9: 304416 | G9: WR | H9: 5.5 | I9: SWRCH22A | J9: 140 | K9: 291528 | L9: =K9/C9 -> 0.9576632 | M9: 4 | N9: 8271
A10: 5LX-01 | B10: 96 | C10: 203424 | G10: WR | H10: 5.5 | I10: SWRY 11 | J10: 96 | K10: 201333 | L10: =K10/C10 -> 0.98972098
A11: 4KX-07 | B11: 48 | C11: 102096 | G11: WR | H11: 5.5 | I11: SWRCH8A | J11: 48 | K11: 100840 | L11: =K11/C11 -> 0.98769785
A12: 3HX-13 | B12: 24 | C12: 51168 | G12: WR | H12: 5.5 | I12: Bj KT 67A | J12: 24 | K12: 50848 | L12: =K12/C12 -> 0.99374609
A13: 5GX-01 | B13: 123 | C13: 259407 | G13: BIC | H13: P.8 | I13: BjTPG280 | J13: 123 | K13: 256161 | L13: =K13/C13 -> 0.98748684
G14: WR | L14: =K14/C14 -> #DIV/0!
G15: WR | L15: =K15/C15 -> #DIV/0!
B16: =SUM(B7:B15) -> 485 | C16: =SUM(C7:C15) -> 1026419 | D16: =SUM(D7:D15) -> 0 | E16: =SUM(E7:E15) -> 0 | F16: =E16/C16 -> 0 | J16: =SUM(J7:J15) -> 481 | K16: =SUM(K7:K15) -> 1004937 | L16: =K16/C16 -> 0.97907093 | M16: =SUM(M7:M15) -> 4 | N16: =SUM(N7:N15) -> 8271
A17: Total Production A1 + WIP | K17: =K16+N16 -> 1013208 | L17: =K17/C16 -> 0.98712904
A18: MONTH-TO-DATE
A19: BILLET | G19: PRODUCT
A20: Rolled | D20: Cobble | G20: A1 | M20: WIP
B21: Pc | C21: Kg | D21: Pc | E21: Kg | F21: % | G21: Type | J21: Coil | K21: Kg | L21: Yield | M21: Coil | N21: Kg
B22: ='6'!B22+B7+B8+B9+B10+B11+B12 -> 560 | C22: ='6'!C22+C7+C8+C9+C10+C11+C12 -> 1185816 | D22: ='6'!D22+D7+D8+D9+D10+D11+D12 -> 1 | E22: ='6'!E22+E7+E8+E9+E10+E11+E12 -> 2109 | F22: =E22/C22 -> 0.0017785221 | G22: WR | J22: ='6'!J22+J7+J8+J9+J10+J11+J12 -> 554 | K22: ='6'!K22+K7+K8+K9+K10+K11+K12 -> 1157610 | L22: =K22/C22 -> 0.97621385 | M22: ='6'!M22+M7+M8+M9+M10+M11+M12 -> 5 | N22: ='6'!N22+N7+N8+N9+N10+N11+N12 -> 10326
B23: ='6'!B23+B13 -> 371 | C23: ='6'!C23+C13 -> 782439 | D23: ='6'!D23+D13 -> 5 | E23: ='6'!E23+E13 -> 10545 | F23: =E23/C23 -> 0.013477089 | G23: BIC | J23: ='6'!J23+J13 -> 362 | K23: ='6'!K23+K13 -> 753199 | L23: =K23/C23 -> 0.96262967 | M23: ='6'!M23+M13 -> 4 | N23: ='6'!N23+N13 -> 7662
B24: ='6'!B24 -> 0 | C24: ='6'!C24 -> 0 | D24: ='6'!D24 -> 0 | E24: ='6'!E24 -> 0 | F24: =E24/C24 -> #DIV/0! | G24: MIC | J24: ='6'!J24 -> 0 | K24: ='6'!K24 -> 0 | L24: =K24/C24 -> #DIV/0! | M24: ='6'!M24 -> 0 | N24: ='6'!N24 -> 0
B26: =SUM(B21:B25) -> 931 | C26: =SUM(C21:C25) -> 1968255 | D26: =SUM(D21:D25) -> 6 | E26: =SUM(E22:E25) -> 12654 | F26: =E26/C26 -> 0.006429045 | J26: =SUM(J22:J25) -> 916 | K26: =SUM(K22:K25) -> 1910809 | L26: =K26/C26 -> 0.97081374 | M26: =SUM(M22:M25) -> 9 | N26: =SUM(N22:N25) -> 17988
A27: Total Production A1 + WIP | K27: =K26+N26 -> 1928797 | L27: =K27/C26 -> 0.9799528
A29: Type | B29: Section | C29: Grade | D29: Coil | E29: Kg | G29: Type | H29: Section | I29: Grade | J29: Coil | K29: Kg | M29: Type | N29: Section | O29: Grade | P29: Coil | Q29: Kg
A30: ='6'!A30 -> BIC | B30: ='6'!B30 -> P.6 | C30: ='6'!C30 -> BjTPG280 | D30: ='6'!D30 -> 239 | E30: ='6'!E30 -> 497038 | G30: ='6'!G30 -> WR | H30: ='6'!H30 -> 0 | I30: ='6'!I30 -> 0 | J30: ='6'!J30 -> 0 | K30: ='6'!K30 -> 0 | M30: ='6'!M30 -> WR | N30: ='6'!N30 -> 0 | O30: ='6'!O30 -> 0 | P30: ='6'!P30 -> 0 | Q30: ='6'!Q30 -> 0
A31: ='6'!A31 -> WR | B31: ='6'!B31 -> 6.5 | C31: ='6'!C31 -> 8 | D31: ='6'!D31 -> 144 | E31: ='6'!E31 -> 301505 | G31: ='6'!G31 -> WR | H31: ='6'!H31 -> 0 | I31: ='6'!I31 -> 0 | J31: ='6'!J31 -> 0 | K31: ='6'!K31 -> 0 | M31: ='6'!M31 -> WR | N31: ='6'!N31 -> 0 | O31: ='6'!O31 -> 0 | P31: ='6'!P31 -> 0 | Q31: ='6'!Q31 -> 0
A32: ='6'!A32 -> WR | B32: ='6'!B32 -> 6.5 | C32: ='6'!C32 -> 10 | D32: ='6'!D32+J7 -> 48 | E32: ='6'!E32+K7 -> 99149 | G32: ='6'!G32 -> WR | H32: ='6'!H32 -> 0 | I32: ='6'!I32 -> 0 | J32: ='6'!J32 -> 0 | K32: ='6'!K32 -> 0 | M32: ='6'!M32 -> WR | N32: ='6'!N32 -> 0 | O32: ='6'!O32 -> 0 | P32: ='6'!P32 -> 0 | Q32: ='6'!Q32 -> 0
A33: ='6'!A33 -> WR | B33: ='6'!B33 -> 6.5 | C33: ='6'!C33 -> 15 | D33: ='6'!D33 -> 6 | E33: ='6'!E33 -> 12304 | G33: ='6'!G33 -> WR | H33: ='6'!H33 -> 0 | I33: ='6'!I33 -> 0 | J33: ='6'!J33 -> 0 | K33: ='6'!K33 -> 0 | M33: ='6'!M33 -> WR | N33: ='6'!N33 -> 0 | O33: ='6'!O33 -> 0 | P33: ='6'!P33 -> 0 | Q33: ='6'!Q33 -> 0
A34: ='6'!A34 -> WR | B34: 5.5 | C34: 6 | D34: =J8 -> 48 | E34: =K8 -> 100103 | G34: ='6'!G34 -> WR | H34: ='6'!H34 -> 0 | I34: ='6'!I34 -> 0 | J34: ='6'!J34 -> 0 | K34: ='6'!K34 -> 0 | M34: ='6'!M34 -> WR | N34: ='6'!N34 -> 0 | O34: ='6'!O34 -> 0 | P34: ='6'!P34 -> 0 | Q34: ='6'!Q34 -> 0
A35: ='6'!A35 -> WR | B35: 5.5 | C35: 8.A | D35: =J11 -> 48 | E35: =K11 -> 100840 | G35: ='6'!G35 -> WR | H35: ='6'!H35 -> 0 | I35: ='6'!I35 -> 0 | J35: ='6'!J35 -> 0 | K35: ='6'!K35 -> 0 | M35: ='6'!M35 -> WR | N35: ='6'!N35 -> 0 | O35: ='6'!O35 -> 0 | P35: ='6'!P35 -> 0 | Q35: ='6'!Q35 -> 0
A36: ='6'!A36 -> WR | B36: 5.5 | C36: 22.A | D36: =J9 -> 140 | E36: =K9 -> 291528 | G36: ='6'!G36 -> WR | H36: ='6'!H36 -> 0 | I36: ='6'!I36 -> 0 | J36: ='6'!J36 -> 0 | K36: ='6'!K36 -> 0 | M36: ='6'!M36 -> WR | N36: ='6'!N36 -> 0 | O36: ='6'!O36 -> 0 | P36: ='6'!P36 -> 0 | Q36: ='6'!Q36 -> 0
A37: ='6'!A37 -> WR | B37: 5.5 | C37: Y.11 | D37: =J10 -> 96 | E37: =K10 -> 201333 | G37: ='6'!G37 -> WR | H37: ='6'!H37 -> 0 | I37: ='6'!I37 -> 0 | J37: ='6'!J37 -> 0 | K37: ='6'!K37 -> 0 | M37: ='6'!M37 -> WR | N37: ='6'!N37 -> 0 | O37: ='6'!O37 -> 0 | P37: ='6'!P37 -> 0 | Q37: ='6'!Q37 -> 0
A38: ='6'!A38 -> WR | B38: 5.5 | C38: 67.A | D38: =J12 -> 24 | E38: =K12 -> 50848 | G38: ='6'!G38 -> WR | H38: ='6'!H38 -> 0 | I38: ='6'!I38 -> 0 | J38: ='6'!J38 -> 0 | K38: ='6'!K38 -> 0 | M38: ='6'!M38 -> WR | N38: ='6'!N38 -> 0 | O38: ='6'!O38 -> 0 | P38: ='6'!P38 -> 0 | Q38: ='6'!Q38 -> 0
A39: BIC | B39: P.8 | C39: BjTPG280 | D39: =J13 -> 123 | E39: =K13 -> 256161 | G39: ='6'!G39 -> WR | H39: ='6'!H39 -> 0 | I39: ='6'!I39 -> 0 | J39: ='6'!J39 -> 0 | K39: ='6'!K39 -> 0 | M39: ='6'!M39 -> WR | N39: ='6'!N39 -> 0 | O39: ='6'!O39 -> 0 | P39: ='6'!P39 -> 0 | Q39: ='6'!Q39 -> 0
A40: ='6'!A40 -> WR | B40: ='6'!B40 -> 0 | C40: ='6'!C40 -> 0 | D40: ='6'!D40 -> 0 | E40: ='6'!E40 -> 0 | G40: ='6'!G40 -> WR | H40: ='6'!H40 -> 0 | I40: ='6'!I40 -> 0 | J40: ='6'!J40 -> 0 | K40: ='6'!K40 -> 0 | M40: ='6'!M40 -> WR | N40: ='6'!N40 -> 0 | O40: ='6'!O40 -> 0 | P40: ='6'!P40 -> 0 | Q40: ='6'!Q40 -> 0
A41: ='6'!A41 -> WR | B41: ='6'!B41 -> 0 | C41: ='6'!C41 -> 0 | D41: ='6'!D41 -> 0 | E41: ='6'!E41 -> 0 | G41: ='6'!G41 -> WR | H41: ='6'!H41 -> 0 | I41: ='6'!I41 -> 0 | J41: ='6'!J41 -> 0 | K41: ='6'!K41 -> 0 | M41: ='6'!M41 -> WR | N41: ='6'!N41 -> 0 | O41: ='6'!O41 -> 0 | P41: ='6'!P41 -> 0 | Q41: ='6'!Q41 -> 0
A42: ='6'!A42 -> WR | B42: ='6'!B42 -> 0 | C42: ='6'!C42 -> 0 | D42: ='6'!D42 -> 0 | E42: ='6'!E42 -> 0 | G42: ='6'!G42 -> WR | H42: ='6'!H42 -> 0 | I42: ='6'!I42 -> 0 | J42: ='6'!J42 -> 0 | K42: ='6'!K42 -> 0 | M42: ='6'!M42 -> WR | N42: ='6'!N42 -> 0 | O42: ='6'!O42 -> 0 | P42: ='6'!P42 -> 0 | Q42: ='6'!Q42 -> 0
...

Sheet 8
A1: TMS 4 | B1: WR | P1: Page | Q1: 1/2
A2: DAILY PRODUCTION REPORT
A3: ='7'!A3:Q3+1 -> 46030
A4: BILLET | G4: PRODUCT
A5: Rolled | D5: Cobble | G5: A1 | M5: WIP
A6: ID | B6: Pc | C6: Kg | D6: Pc | E6: Kg | F6: % | G6: Type | H6: Section | I6: Grade | J6: Coil | K6: Kg | L6: Yield | M6: Coil | N6: Kg
A7: 5GX-01 | B7: 69 | C7: 145521 | G7: BIC | H7: P.8 | I7: BjTPG280 | J7: 69 | K7: 144051 | L7: =K7/C7 -> 0.98989837
A8: 5LL-001 | B8: 192 | C8: 400704 | G8: BIC | H8: S.8 | I8: BjTSG420 | J8: 192 | K8: =392984+2054 -> 395038 | L8: =K8/C8 -> 0.98585989
A9: 5LL-001 | B9: 144 | C9: 300528 | G9: BIC | H9: S.10 | I9: BjTSG420 | J9: 144 | K9: 295842 | L9: =K9/C9 -> 0.98440744
A10: 5KX-06 | B10: 101 | C10: 214019 | G10: WR | H10: 5.5 | I10: Bj KR 6 | J10: 101 | K10: 211729 | L10: =K10/C10 -> 0.98930002
G11: WR | L11: =K11/C11 -> #DIV/0!
G12: WR | L12: =K12/C12 -> #DIV/0!
G13: WR | L13: =K13/C13 -> #DIV/0!
G14: WR | L14: =K14/C14 -> #DIV/0!
G15: WR | L15: =K15/C15 -> #DIV/0!
B16: =SUM(B7:B15) -> 506 | C16: =SUM(C7:C15) -> 1060772 | D16: =SUM(D7:D15) -> 0 | E16: =SUM(E7:E15) -> 0 | F16: =E16/C16 -> 0 | J16: =SUM(J7:J15) -> 506 | K16: =SUM(K7:K15) -> 1046660 | L16: =K16/C16 -> 0.98669648 | M16: =SUM(M7:M15) -> 0 | N16: =SUM(N7:N15) -> 0
A17: Total Production A1 + WIP | K17: =K16+N16 -> 1046660 | L17: =K17/C16 -> 0.98669648
A18: MONTH-TO-DATE
A19: BILLET | G19: PRODUCT
A20: Rolled | D20: Cobble | G20: A1 | M20: WIP
B21: Pc | C21: Kg | D21: Pc | E21: Kg | F21: % | G21: Type | J21: Coil | K21: Kg | L21: Yield | M21: Coil | N21: Kg
B22: ='7'!B22+B10 -> 661 | C22: ='7'!C22+C10 -> 1399835 | D22: ='7'!D22+D10 -> 1 | E22: ='7'!E22+E10 -> 2109 | F22: =E22/C22 -> 0.0015066061 | G22: WR | J22: ='7'!J22+J10 -> 655 | K22: ='7'!K22+K10 -> 1369339 | L22: =K22/C22 -> 0.97821458 | M22: ='7'!M22+M10 -> 5 | N22: ='7'!N22+N10 -> 10326
B23: ='7'!B23+B7+B8+B9 -> 776 | C23: ='7'!C23+C7+C8+C9 -> 1629192 | D23: ='7'!D23+D7+D8+D9 -> 5 | E23: ='7'!E23+E7+E8+E9 -> 10545 | F23: =E23/C23 -> 0.0064725336 | G23: BIC | J23: ='7'!J23+J7+J8+J9 -> 767 | K23: ='7'!K23+K7+K8+K9 -> 1588130 | L23: =K23/C23 -> 0.9747961 | M23: ='7'!M23+M7+M8+M9 -> 4 | N23: ='7'!N23+N7+N8+N9 -> 7662
B24: ='7'!B24 -> 0 | C24: ='7'!C24 -> 0 | D24: ='7'!D24 -> 0 | E24: ='7'!E24 -> 0 | F24: =E24/C24 -> #DIV/0! | G24: MIC | J24: ='7'!J24 -> 0 | K24: ='7'!K24 -> 0 | L24: =K24/C24 -> #DIV/0! | M24: ='7'!M24 -> 0 | N24: ='7'!N24 -> 0
B26: =SUM(B21:B25) -> 1437 | C26: =SUM(C21:C25) -> 3029027 | D26: =SUM(D21:D25) -> 6 | E26: =SUM(E22:E25) -> 12654 | F26: =E26/C26 -> 0.0041775791 | J26: =SUM(J22:J25) -> 1422 | K26: =SUM(K22:K25) -> 2957469 | L26: =K26/C26 -> 0.97637591 | M26: =SUM(M22:M25) -> 9 | N26: =SUM(N22:N25) -> 17988
A27: Total Production A1 + WIP | K27: =K26+N26 -> 2975457 | L27: =K27/C26 -> 0.98231445
A29: Type | B29: Section | C29: Grade | D29: Coil | E29: Kg | G29: Type | H29: Section | I29: Grade | J29: Coil | K29: Kg | M29: Type | N29: Section | O29: Grade | P29: Coil | Q29: Kg
A30: ='7'!A30 -> BIC | B30: ='7'!B30 -> P.6 | C30: ='7'!C30 -> BjTPG280 | D30: ='7'!D30 -> 239 | E30: ='7'!E30 -> 497038 | G30: ='7'!G30 -> WR | H30: ='7'!H30 -> 0 | I30: ='7'!I30 -> 0 | J30: ='7'!J30 -> 0 | K30: ='7'!K30 -> 0 | M30: ='7'!M30 -> WR | N30: ='7'!N30 -> 0 | O30: ='7'!O30 -> 0 | P30: ='7'!P30 -> 0 | Q30: ='7'!Q30 -> 0
A31: ='7'!A31 -> WR | B31: ='7'!B31 -> 6.5 | C31: ='7'!C31 -> 8 | D31: ='7'!D31 -> 144 | E31: ='7'!E31 -> 301505 | G31: ='7'!G31 -> WR | H31: ='7'!H31 -> 0 | I31: ='7'!I31 -> 0 | J31: ='7'!J31 -> 0 | K31: ='7'!K31 -> 0 | M31: ='7'!M31 -> WR | N31: ='7'!N31 -> 0 | O31: ='7'!O31 -> 0 | P31: ='7'!P31 -> 0 | Q31: ='7'!Q31 -> 0
A32: ='7'!A32 -> WR | B32: ='7'!B32 -> 6.5 | C32: ='7'!C32 -> 10 | D32: ='7'!D32 -> 48 | E32: ='7'!E32 -> 99149 | G32: ='7'!G32 -> WR | H32: ='7'!H32 -> 0 | I32: ='7'!I32 -> 0 | J32: ='7'!J32 -> 0 | K32: ='7'!K32 -> 0 | M32: ='7'!M32 -> WR | N32: ='7'!N32 -> 0 | O32: ='7'!O32 -> 0 | P32: ='7'!P32 -> 0 | Q32: ='7'!Q32 -> 0
A33: ='7'!A33 -> WR | B33: ='7'!B33 -> 6.5 | C33: ='7'!C33 -> 15 | D33: ='7'!D33 -> 6 | E33: ='7'!E33 -> 12304 | G33: ='7'!G33 -> WR | H33: ='7'!H33 -> 0 | I33: ='7'!I33 -> 0 | J33: ='7'!J33 -> 0 | K33: ='7'!K33 -> 0 | M33: ='7'!M33 -> WR | N33: ='7'!N33 -> 0 | O33: ='7'!O33 -> 0 | P33: ='7'!P33 -> 0 | Q33: ='7'!Q33 -> 0
A34: ='7'!A34 -> WR | B34: ='7'!B34 -> 5.5 | C34: ='7'!C34 -> 6 | D34: ='7'!D34+J10 -> 149 | E34: ='7'!E34+K10 -> 311832 | G34: ='7'!G34 -> WR | H34: ='7'!H34 -> 0 | I34: ='7'!I34 -> 0 | J34: ='7'!J34 -> 0 | K34: ='7'!K34 -> 0 | M34: ='7'!M34 -> WR | N34: ='7'!N34 -> 0 | O34: ='7'!O34 -> 0 | P34: ='7'!P34 -> 0 | Q34: ='7'!Q34 -> 0
A35: ='7'!A35 -> WR | B35: ='7'!B35 -> 5.5 | C35: ='7'!C35 -> 8.A | D35: ='7'!D35 -> 48 | E35: ='7'!E35 -> 100840 | G35: ='7'!G35 -> WR | H35: ='7'!H35 -> 0 | I35: ='7'!I35 -> 0 | J35: ='7'!J35 -> 0 | K35: ='7'!K35 -> 0 | M35: ='7'!M35 -> WR | N35: ='7'!N35 -> 0 | O35: ='7'!O35 -> 0 | P35: ='7'!P35 -> 0 | Q35: ='7'!Q35 -> 0
A36: ='7'!A36 -> WR | B36: ='7'!B36 -> 5.5 | C36: ='7'!C36 -> 22.A | D36: ='7'!D36 -> 140 | E36: ='7'!E36 -> 291528 | G36: ='7'!G36 -> WR | H36: ='7'!H36 -> 0 | I36: ='7'!I36 -> 0 | J36: ='7'!J36 -> 0 | K36: ='7'!K36 -> 0 | M36: ='7'!M36 -> WR | N36: ='7'!N36 -> 0 | O36: ='7'!O36 -> 0 | P36: ='7'!P36 -> 0 | Q36: ='7'!Q36 -> 0
A37: ='7'!A37 -> WR | B37: ='7'!B37 -> 5.5 | C37: ='7'!C37 -> Y.11 | D37: ='7'!D37 -> 96 | E37: ='7'!E37 -> 201333 | G37: ='7'!G37 -> WR | H37: ='7'!H37 -> 0 | I37: ='7'!I37 -> 0 | J37: ='7'!J37 -> 0 | K37: ='7'!K37 -> 0 | M37: ='7'!M37 -> WR | N37: ='7'!N37 -> 0 | O37: ='7'!O37 -> 0 | P37: ='7'!P37 -> 0 | Q37: ='7'!Q37 -> 0
A38: ='7'!A38 -> WR | B38: ='7'!B38 -> 5.5 | C38: ='7'!C38 -> 67.A | D38: ='7'!D38 -> 24 | E38: ='7'!E38 -> 50848 | G38: ='7'!G38 -> WR | H38: ='7'!H38 -> 0 | I38: ='7'!I38 -> 0 | J38: ='7'!J38 -> 0 | K38: ='7'!K38 -> 0 | M38: ='7'!M38 -> WR | N38: ='7'!N38 -> 0 | O38: ='7'!O38 -> 0 | P38: ='7'!P38 -> 0 | Q38: ='7'!Q38 -> 0
A39: ='7'!A39 -> BIC | B39: ='7'!B39 -> P.8 | C39: ='7'!C39 -> BjTPG280 | D39: ='7'!D39+J7 -> 192 | E39: ='7'!E39+K7 -> 400212 | G39: ='7'!G39 -> WR | H39: ='7'!H39 -> 0 | I39: ='7'!I39 -> 0 | J39: ='7'!J39 -> 0 | K39: ='7'!K39 -> 0 | M39: ='7'!M39 -> WR | N39: ='7'!N39 -> 0 | O39: ='7'!O39 -> 0 | P39: ='7'!P39 -> 0 | Q39: ='7'!Q39 -> 0
A40: BIC | B40: S.8 | C40: BjTSG420 | D40: =J8 -> 192 | E40: =K8 -> 395038 | G40: ='7'!G40 -> WR | H40: ='7'!H40 -> 0 | I40: ='7'!I40 -> 0 | J40: ='7'!J40 -> 0 | K40: ='7'!K40 -> 0 | M40: ='7'!M40 -> WR | N40: ='7'!N40 -> 0 | O40: ='7'!O40 -> 0 | P40: ='7'!P40 -> 0 | Q40: ='7'!Q40 -> 0
A41: BIC | B41: S.10 | C41: BjTSG420 | D41: =J9 -> 144 | E41: =K9 -> 295842 | G41: ='7'!G41 -> WR | H41: ='7'!H41 -> 0 | I41: ='7'!I41 -> 0 | J41: ='7'!J41 -> 0 | K41: ='7'!K41 -> 0 | M41: ='7'!M41 -> WR | N41: ='7'!N41 -> 0 | O41: ='7'!O41 -> 0 | P41: ='7'!P41 -> 0 | Q41: ='7'!Q41 -> 0
A42: ='7'!A42 -> WR | B42: ='7'!B42 -> 0 | C42: ='7'!C42 -> 0 | D42: ='7'!D42 -> 0 | E42: ='7'!E42 -> 0 | G42: ='7'!G42 -> WR | H42: ='7'!H42 -> 0 | I42: ='7'!I42 -> 0 | J42: ='7'!J42 -> 0 | K42: ='7'!K42 -> 0 | M42: ='7'!M42 -> WR | N42: ='7'!N42 -> 0 | O42: ='7'!O42 -> 0 | P42: ='7'!P42 -> 0 | Q42: ='7'!Q42 -> 0
...

Sheet 9
A1: TMS 4 | B1: WR | P1: Page | Q1: 1/2
A2: DAILY PRODUCTION REPORT
A3: ='8'!A3:Q3+1 -> 46031
A4: BILLET | G4: PRODUCT
A5: Rolled | D5: Cobble | G5: A1 | M5: WIP
A6: ID | B6: Pc | C6: Kg | D6: Pc | E6: Kg | F6: % | G6: Type | H6: Section | I6: Grade | J6: Coil | K6: Kg | L6: Yield | M6: Coil | N6: Kg
A7: 5KX-06 | B7: 139 | C7: 294541 | G7: WR | H7: 5.5 | I7: Bj KR 6 | J7: 139 | K7: 292249 | L7: =K7/C7 -> 0.9922184
A8: 5LX-03 | B8: 144 | C8: 305424 | G8: WR | H8: 5.5 | I8: Bj KR 8 | J8: 144 | K8: 302399 | L8: =K8/C8 -> 0.99009574
A9: 5LX-01 | B9: 144 | C9: 305136 | D9: 4 | E9: 8476 | F9: =E9/C9 -> 0.027777778 | G9: WR | H9: 5.5 | I9: SWRY 11 | J9: 139 | K9: 290875 | L9: =K9/C9 -> 0.95326346 | M9: 1 | N9: 2098
A10: 5LX-01 | B10: 73 | C10: 154687 | G10: WR | H10: 5.5 | I10: SWRY11 | J10: 73 | K10: 153722 | L10: =K10/C10 -> 0.9937616
G11: WR | L11: =K11/C11 -> #DIV/0!
G12: WR | L12: =K12/C12 -> #DIV/0!
G13: WR | L13: =K13/C13 -> #DIV/0!
G14: WR | L14: =K14/C14 -> #DIV/0!
G15: WR | L15: =K15/C15 -> #DIV/0!
B16: =SUM(B7:B15) -> 500 | C16: =SUM(C7:C15) -> 1059788 | D16: =SUM(D7:D15) -> 4 | E16: =SUM(E7:E15) -> 8476 | F16: =E16/C16 -> 0.007997826 | J16: =SUM(J7:J15) -> 495 | K16: =SUM(K7:K15) -> 1039245 | L16: =K16/C16 -> 0.98061593 | M16: =SUM(M7:M15) -> 1 | N16: =SUM(N7:N15) -> 2098
A17: Total Production A1 + WIP | K17: =K16+N16 -> 1041343 | L17: =K17/C16 -> 0.98259558
A18: MONTH-TO-DATE
A19: BILLET | G19: PRODUCT
A20: Rolled | D20: Cobble | G20: A1 | M20: WIP
B21: Pc | C21: Kg | D21: Pc | E21: Kg | F21: % | G21: Type | J21: Coil | K21: Kg | L21: Yield | M21: Coil | N21: Kg
B22: ='8'!B22+'9'!B16 -> 1161 | C22: ='8'!C22+'9'!C16 -> 2459623 | D22: ='8'!D22+'9'!D16 -> 5 | E22: ='8'!E22+'9'!E16 -> 10585 | F22: =E22/C22 -> 0.004303505 | G22: WR | J22: ='8'!J22+'9'!J16 -> 1150 | K22: ='8'!K22+'9'!K16 -> 2408584 | L22: =K22/C22 -> 0.97924926 | M22: ='8'!M22+'9'!M16 -> 6 | N22: ='8'!N22+'9'!N16 -> 12424
B23: ='8'!B23 -> 776 | C23: ='8'!C23 -> 1629192 | D23: ='8'!D23 -> 5 | E23: ='8'!E23 -> 10545 | F23: =E23/C23 -> 0.0064725336 | G23: BIC | J23: ='8'!J23 -> 767 | K23: ='8'!K23 -> 1588130 | L23: =K23/C23 -> 0.9747961 | M23: ='8'!M23 -> 4 | N23: ='8'!N23 -> 7662
B24: ='8'!B24 -> 0 | C24: ='8'!C24 -> 0 | D24: ='8'!D24 -> 0 | E24: ='8'!E24 -> 0 | F24: =E24/C24 -> #DIV/0! | G24: MIC | J24: ='8'!J24 -> 0 | K24: ='8'!K24 -> 0 | L24: =K24/C24 -> #DIV/0! | M24: ='8'!M24 -> 0 | N24: ='8'!N24 -> 0
B26: =SUM(B21:B25) -> 1937 | C26: =SUM(C21:C25) -> 4088815 | D26: =SUM(D21:D25) -> 10 | E26: =SUM(E22:E25) -> 21130 | F26: =E26/C26 -> 0.0051677564 | J26: =SUM(J22:J25) -> 1917 | K26: =SUM(K22:K25) -> 3996714 | L26: =K26/C26 -> 0.97747489 | M26: =SUM(M22:M25) -> 10 | N26: =SUM(N22:N25) -> 20086
A27: Total Production A1 + WIP | K27: =K26+N26 -> 4016800 | L27: =K27/C26 -> 0.98238732
A29: Type | B29: Section | C29: Grade | D29: Coil | E29: Kg | G29: Type | H29: Section | I29: Grade | J29: Coil | K29: Kg | M29: Type | N29: Section | O29: Grade | P29: Coil | Q29: Kg
A30: ='8'!A30 -> BIC | B30: ='8'!B30 -> P.6 | C30: ='8'!C30 -> BjTPG280 | D30: ='8'!D30 -> 239 | E30: ='8'!E30 -> 497038 | G30: ='8'!G30 -> WR | H30: ='8'!H30 -> 0 | I30: ='8'!I30 -> 0 | J30: ='8'!J30 -> 0 | K30: ='8'!K30 -> 0 | M30: ='8'!M30 -> WR | N30: ='8'!N30 -> 0 | O30: ='8'!O30 -> 0 | P30: ='8'!P30 -> 0 | Q30: ='8'!Q30 -> 0
A31: ='8'!A31 -> WR | B31: ='8'!B31 -> 6.5 | C31: ='8'!C31 -> 8 | D31: ='8'!D31 -> 144 | E31: ='8'!E31 -> 301505 | G31: ='8'!G31 -> WR | H31: ='8'!H31 -> 0 | I31: ='8'!I31 -> 0 | J31: ='8'!J31 -> 0 | K31: ='8'!K31 -> 0 | M31: ='8'!M31 -> WR | N31: ='8'!N31 -> 0 | O31: ='8'!O31 -> 0 | P31: ='8'!P31 -> 0 | Q31: ='8'!Q31 -> 0
A32: ='8'!A32 -> WR | B32: ='8'!B32 -> 6.5 | C32: ='8'!C32 -> 10 | D32: ='8'!D32 -> 48 | E32: ='8'!E32 -> 99149 | G32: ='8'!G32 -> WR | H32: ='8'!H32 -> 0 | I32: ='8'!I32 -> 0 | J32: ='8'!J32 -> 0 | K32: ='8'!K32 -> 0 | M32: ='8'!M32 -> WR | N32: ='8'!N32 -> 0 | O32: ='8'!O32 -> 0 | P32: ='8'!P32 -> 0 | Q32: ='8'!Q32 -> 0
A33: ='8'!A33 -> WR | B33: ='8'!B33 -> 6.5 | C33: ='8'!C33 -> 15 | D33: ='8'!D33 -> 6 | E33: ='8'!E33 -> 12304 | G33: ='8'!G33 -> WR | H33: ='8'!H33 -> 0 | I33: ='8'!I33 -> 0 | J33: ='8'!J33 -> 0 | K33: ='8'!K33 -> 0 | M33: ='8'!M33 -> WR | N33: ='8'!N33 -> 0 | O33: ='8'!O33 -> 0 | P33: ='8'!P33 -> 0 | Q33: ='8'!Q33 -> 0
A34: ='8'!A34 -> WR | B34: ='8'!B34 -> 5.5 | C34: ='8'!C34 -> 6 | D34: ='8'!D34+J7 -> 288 | E34: ='8'!E34+K7 -> 604081 | G34: ='8'!G34 -> WR | H34: ='8'!H34 -> 0 | I34: ='8'!I34 -> 0 | J34: ='8'!J34 -> 0 | K34: ='8'!K34 -> 0 | M34: ='8'!M34 -> WR | N34: ='8'!N34 -> 0 | O34: ='8'!O34 -> 0 | P34: ='8'!P34 -> 0 | Q34: ='8'!Q34 -> 0
A35: ='8'!A35 -> WR | B35: ='8'!B35 -> 5.5 | C35: ='8'!C35 -> 8.A | D35: ='8'!D35 -> 48 | E35: ='8'!E35 -> 100840 | G35: ='8'!G35 -> WR | H35: ='8'!H35 -> 0 | I35: ='8'!I35 -> 0 | J35: ='8'!J35 -> 0 | K35: ='8'!K35 -> 0 | M35: ='8'!M35 -> WR | N35: ='8'!N35 -> 0 | O35: ='8'!O35 -> 0 | P35: ='8'!P35 -> 0 | Q35: ='8'!Q35 -> 0
A36: ='8'!A36 -> WR | B36: ='8'!B36 -> 5.5 | C36: ='8'!C36 -> 22.A | D36: ='8'!D36 -> 140 | E36: ='8'!E36 -> 291528 | G36: ='8'!G36 -> WR | H36: ='8'!H36 -> 0 | I36: ='8'!I36 -> 0 | J36: ='8'!J36 -> 0 | K36: ='8'!K36 -> 0 | M36: ='8'!M36 -> WR | N36: ='8'!N36 -> 0 | O36: ='8'!O36 -> 0 | P36: ='8'!P36 -> 0 | Q36: ='8'!Q36 -> 0
A37: ='8'!A37 -> WR | B37: ='8'!B37 -> 5.5 | C37: ='8'!C37 -> Y.11 | D37: ='8'!D37+J9+J10 -> 308 | E37: ='8'!E37+K9+K10 -> 645930 | G37: ='8'!G37 -> WR | H37: ='8'!H37 -> 0 | I37: ='8'!I37 -> 0 | J37: ='8'!J37 -> 0 | K37: ='8'!K37 -> 0 | M37: ='8'!M37 -> WR | N37: ='8'!N37 -> 0 | O37: ='8'!O37 -> 0 | P37: ='8'!P37 -> 0 | Q37: ='8'!Q37 -> 0
A38: ='8'!A38 -> WR | B38: ='8'!B38 -> 5.5 | C38: ='8'!C38 -> 67.A | D38: ='8'!D38 -> 24 | E38: ='8'!E38 -> 50848 | G38: ='8'!G38 -> WR | H38: ='8'!H38 -> 0 | I38: ='8'!I38 -> 0 | J38: ='8'!J38 -> 0 | K38: ='8'!K38 -> 0 | M38: ='8'!M38 -> WR | N38: ='8'!N38 -> 0 | O38: ='8'!O38 -> 0 | P38: ='8'!P38 -> 0 | Q38: ='8'!Q38 -> 0
A39: ='8'!A39 -> BIC | B39: ='8'!B39 -> P.8 | C39: ='8'!C39 -> BjTPG280 | D39: ='8'!D39 -> 192 | E39: ='8'!E39 -> 400212 | G39: ='8'!G39 -> WR | H39: ='8'!H39 -> 0 | I39: ='8'!I39 -> 0 | J39: ='8'!J39 -> 0 | K39: ='8'!K39 -> 0 | M39: ='8'!M39 -> WR | N39: ='8'!N39 -> 0 | O39: ='8'!O39 -> 0 | P39: ='8'!P39 -> 0 | Q39: ='8'!Q39 -> 0
A40: ='8'!A40 -> BIC | B40: ='8'!B40 -> S.8 | C40: ='8'!C40 -> BjTSG420 | D40: ='8'!D40 -> 192 | E40: ='8'!E40 -> 395038 | G40: ='8'!G40 -> WR | H40: ='8'!H40 -> 0 | I40: ='8'!I40 -> 0 | J40: ='8'!J40 -> 0 | K40: ='8'!K40 -> 0 | M40: ='8'!M40 -> WR | N40: ='8'!N40 -> 0 | O40: ='8'!O40 -> 0 | P40: ='8'!P40 -> 0 | Q40: ='8'!Q40 -> 0
A41: ='8'!A41 -> BIC | B41: ='8'!B41 -> S.10 | C41: ='8'!C41 -> BjTSG420 | D41: ='8'!D41 -> 144 | E41: ='8'!E41 -> 295842 | G41: ='8'!G41 -> WR | H41: ='8'!H41 -> 0 | I41: ='8'!I41 -> 0 | J41: ='8'!J41 -> 0 | K41: ='8'!K41 -> 0 | M41: ='8'!M41 -> WR | N41: ='8'!N41 -> 0 | O41: ='8'!O41 -> 0 | P41: ='8'!P41 -> 0 | Q41: ='8'!Q41 -> 0
A42: ='8'!A42 -> WR | B42: 5.5 | C42: 8 | D42: =J8 -> 144 | E42: =K8 -> 302399 | G42: ='8'!G42 -> WR | H42: ='8'!H42 -> 0 | I42: ='8'!I42 -> 0 | J42: ='8'!J42 -> 0 | K42: ='8'!K42 -> 0 | M42: ='8'!M42 -> WR | N42: ='8'!N42 -> 0 | O42: ='8'!O42 -> 0 | P42: ='8'!P42 -> 0 | Q42: ='8'!Q42 -> 0
...

Sheet 10
A1: TMS 4 | B1: WR | P1: Page | Q1: 1/2
A2: DAILY PRODUCTION REPORT
A3: ='9'!A3:Q3+1 -> 46032
A4: BILLET | G4: PRODUCT
A5: Rolled | D5: Cobble | G5: A1 | M5: WIP
A6: ID | B6: Pc | C6: Kg | D6: Pc | E6: Kg | F6: % | G6: Type | H6: Section | I6: Grade | J6: Coil | K6: Kg | L6: Yield | M6: Coil | N6: Kg
A7: 5LX-01 | B7: 152 | C7: 322088 | D7: 1 | E7: 2119 | F7: =E7/C7 -> 0.0065789474 | G7: WR | H7: 5.5 | I7: SWRY11 | J7: 147 | K7: 307583 | L7: =K7/C7 -> 0.95496572 | M7: 4 | N7: 8159
A8: 5LX-01 | B8: 71 | C8: 150449 | G8: WR | H8: 5.5 | I8: SWRY 11 | J8: 71 | K8: 149077 | L8: =K8/C8 -> 0.99088063
A9: 4LX-03 | B9: 144 | C9: 304416 | G9: WR | H9: 5.5 | I9: SWRCH22A | J9: 144 | K9: 301817 | L9: =K9/C9 -> 0.99146234
A10: 5KX-06 | B10: 103 | C10: 218257 | G10: WR | H10: 5.5 | I10: Bj KR 6 | J10: 103 | K10: 216475 | L10: =K10/C10 -> 0.99183531
A11: 5KX-06 | B11: 54 | C11: 114426 | G11: WR | H11: 5.5 | I11: SAE 1006 | J11: 54 | K11: 113601 | L11: =K11/C11 -> 0.9927901
G12: WR | L12: =K12/C12 -> #DIV/0!
G13: WR | L13: =K13/C13 -> #DIV/0!
G14: WR | L14: =K14/C14 -> #DIV/0!
G15: WR | L15: =K15/C15 -> #DIV/0!
B16: =SUM(B7:B15) -> 524 | C16: =SUM(C7:C15) -> 1109636 | D16: =SUM(D7:D15) -> 1 | E16: =SUM(E7:E15) -> 2119 | F16: =E16/C16 -> 0.0019096352 | J16: =SUM(J7:J15) -> 519 | K16: =SUM(K7:K15) -> 1088553 | L16: =K16/C16 -> 0.98100008 | M16: =SUM(M7:M15) -> 4 | N16: =SUM(N7:N15) -> 8159
A17: Total Production A1 + WIP | K17: =K16+N16 -> 1096712 | L17: =K17/C16 -> 0.98835294
A18: MONTH-TO-DATE
A19: BILLET | G19: PRODUCT
A20: Rolled | D20: Cobble | G20: A1 | M20: WIP
B21: Pc | C21: Kg | D21: Pc | E21: Kg | F21: % | G21: Type | J21: Coil | K21: Kg | L21: Yield | M21: Coil | N21: Kg
B22: ='9'!B22+'10'!B16 -> 1685 | C22: ='9'!C22+'10'!C16 -> 3569259 | D22: ='9'!D22+'10'!D16 -> 6 | E22: ='9'!E22+'10'!E16 -> 12704 | F22: =E22/C22 -> 0.0035592822 | G22: WR | J22: ='9'!J22+'10'!J16 -> 1669 | K22: ='9'!K22+'10'!K16 -> 3497137 | L22: =K22/C22 -> 0.97979356 | M22: ='9'!M22+'10'!M16 -> 10 | N22: ='9'!N22+'10'!N16 -> 20583
B23: ='9'!B23 -> 776 | C23: ='9'!C23 -> 1629192 | D23: ='9'!D23 -> 5 | E23: ='9'!E23 -> 10545 | F23: =E23/C23 -> 0.0064725336 | G23: BIC | J23: ='9'!J23 -> 767 | K23: ='9'!K23 -> 1588130 | L23: =K23/C23 -> 0.9747961 | M23: ='9'!M23 -> 4 | N23: ='9'!N23 -> 7662
B24: ='9'!B24 -> 0 | C24: ='9'!C24 -> 0 | D24: ='9'!D24 -> 0 | E24: ='9'!E24 -> 0 | F24: =E24/C24 -> #DIV/0! | G24: MIC | J24: ='9'!J24 -> 0 | K24: ='9'!K24 -> 0 | L24: =K24/C24 -> #DIV/0! | M24: ='9'!M24 -> 0 | N24: ='9'!N24 -> 0
